Workbook
Name NamedRange1: PATHIRAM!$A$1:$AB$1
Name NamedRange1: RING!$A$1:$AB$1
Name NamedRange1: SL!$A$1:$AB$1
Name NamedRange1: STEPS!$A$1:$AB$1
Name NamedRange1: KOLUSU!$A$1:$AB$1
Name NamedRange1: 'DOOR CLOSING'!$A$1:$AB$1
Name NamedRange1: COLLECTION!$A$1:$AB$1
Name NamedRange1: 'DOOR OPEN'!$A$1:$AB$1
Name NamedRange1: 'FAN CLEAN'!$A$1:$AB$1
Name NamedRange1: 'DROPS ARR'!$A$1:$AB$1
Name NamedRange1: PURSE!$A$1:$AB$1
Name NamedRange1: 'PATHIRAM,SL BOX'!$A$1:$AB$1
Name NamedRange1: 'CHAIN ARR'!$A$1:$AB$1
Name NamedRange1: MET.MKT!$A$1:$AB$1
Name NamedRange1: #REF!
Name NamedRange1: CASH!$A$1:$AB$1
Name NamedRange1: 'SIL.ARR (MOR&EVE)'!$A$1:$AB$1
Name NamedRange1: TEA!$A$1:$AB$1
Name NamedRange1: CHAIN!$A$1:$AB$1
Name NamedRange1: 'TRAY ARR'!$A$1:$AB$1
Name NamedRange1: 'MAADI CLEAN'!$A$1:$AB$1
Name NamedRange1: 'EVENING CLEAN'!$A$1:$AB$1
Name NamedRange1: 'DUSTBIN CLEAN'!$A$1:$AB$1
Name NamedRange1: 'MOR CLEAN'!$A$1:$AB$1
Name NamedRange1: DROPS!$A$1:$AB$1
Name NamedRange1: 'DUSTBIN CHECK'!$A$1:$AB$1
Name NamedRange1: CHITTAI!$A$1:$AB$1

Sheet AUTHENTICATION
A1: USERNAME | B1: AUTHENTICATION | C1: PERMISSION KEY
A2: MUTHUKUMAR | B2: MK
A3: VISHNUPRIYA | B3: VP
A4: NIVETHA | B4: NA
A5: CHINNAMMAL | B5: CH

Sheet OVERVIEW 
I1: =OR(TEXT(TODAY()+1, "DDD")="Tue", TEXT(TODAY()+1, "DDD")="Fri") -> TRUE
D2: FALSE | E2: FALSE | F2: FALSE | G2: TRUE | H2: =I1 -> TRUE | I2: =I1 -> TRUE | J2: =I1 -> TRUE | K2: =I1 -> TRUE | L2: TRUE | M2: TRUE | N2: TRUE | O2: TRUE | P2: TRUE | Q2: TRUE | V2: TRUE | W2: TRUE | X2: TRUE | Y2: TRUE | AD2: TRUE | AE2: TRUE | AG2: TRUE | AH2: FALSE | AI2: FALSE | AN2: FALSE | AO2: FALSE | AP2: FALSE
D3: CHITTAI | E3: CASHIER | F3: STEPS | G3: COLLECTION | H3: PATHIRAM,SL BOX | I3: PATHIRAM | J3: SL | K3: KOLUSU | L3: TEA | M3: MET.MKT | N3: SIL.ARR (MOR&EVE) | O3: CHAIN | P3: CHAIN ARRANGE | Q3: DROPS ARRANGE | V3: DROPS | W3: RING | X3: EVENING CLEANING | Y3: DUSTBIN CHECK | AD3: DUSTBIN CLEAN | AE3: TRAY ARRANGE | AG3: SHOP CLOSING | AH3: SHOP OPEN | AI3: MOR CLEAN | AK3: =D30 | AL3: =D29 -> CHITTAI | AN3: PURSE,BAG | AO3: MAADI CLEAN | AP3: FAN CLEAN
A4: =D30 | B4: =D3 -> CHITTAI | D4: =IF($D$2=TRUE,CHITTAI!V2,"") | E4: =IF($E$2=TRUE,CASH!V2,"") | F4: =IF($F$2=TRUE,STEPS!V2,"") | G4: =IF($G$2=TRUE,COLLECTION!V2,"") -> VIJI-2 | H4: =IF($H$2=TRUE,'PATHIRAM,SL BOX'!V2,"") -> RAJI-2 | I4: =IF($I$2=TRUE,PATHIRAM!V2,"") -> SAHANA | J4: =IF($J$2=TRUE,SL!V2,"") -> SUDHARSHINI | K4: =IF($K$2=TRUE,KOLUSU!V2,"") -> DEEPA | L4: =IF($L$2=TRUE,TEA!V2,"") -> JEYANTHI | M4: =IF($M$2=TRUE,MET.MKT!V2,"") -> BHARATHI | N4: =IF($N$2=TRUE,'SIL.ARR (MOR&EVE)'!V2,"") -> CHINNAMMAL | O4: =IF($O$2=TRUE,CHAIN!V2,"") -> RAJI-2 | P4: =IF($P$2=TRUE,'CHAIN ARR'!V2,"") -> KAVIYA | Q4: =IF($Q$2=TRUE,'DROPS ARR'!V2,"") -> SHANTHI | S4: =D30 | T4: =D3 -> CHITTAI | V4: =IF($V$2=TRUE,DROPS!V2,"") -> JEYANTHI | W4: =IF($W$2=TRUE,RING!V2,"") -> CHINNAMMAL | X4: =IF($X$2=TRUE,'EVENING CLEAN'!V2,"") -> SANTHIYA | Y4: =IF($Y$2=TRUE,'DUSTBIN CHECK'!V2,"") -> VIJI-2 | AA4: =Y30 -> VIJI-2 | AB4: =Y3 -> DUSTBIN CHECK | AD4: =IF($AD$2=TRUE,'DUSTBIN CLEAN'!V2,"") -> SANTHIYA | AE4: =IF($AE$2=TRUE,'TRAY ARR'!V2,"") -> MUTHUPRIYA | AG4: =IF($AG$2=TRUE,'DOOR CLOSING'!V2,"") -> SAKTHIVEL 2 | AH4: =IF(WEEKDAY(TODAY()+1)=1, "PARIMANAM",'DOOR OPEN'!V2) -> MANIMARAN | AI4: =IF($AI$2=TRUE,'MOR CLEAN'!X2,'MOR CLEAN'!V2) -> RANI | AK4: =E30 | AL4: =E29 -> CASHIER | AN4: =IF($AN$2=TRUE,PURSE!X2,PURSE!V2) -> CHINNAMMAL | AO4: =IF($AO$2=TRUE,'MAADI CLEAN'!X2,'MAADI CLEAN'!V2) -> VIDHYA | AP4: =IF($AP$2=TRUE,'FAN CLEAN'!X2,'FAN CLEAN'!V2) -> SHANTHI
A5: =E30 | B5: =E3 -> CASHIER | D5: =IF($D$2=TRUE,CHITTAI!V3,"") | E5: =IF($E$2=TRUE,CASH!V3,"") | F5: =IF($F$2=TRUE,STEPS!V3,"") | G5: =IF($G$2=TRUE,COLLECTION!V3,"") -> BHARATHI | H5: =IF($H$2=TRUE,'PATHIRAM,SL BOX'!V3,"") -> VIJI-1 | I5: =IF($I$2=TRUE,PATHIRAM!V3,"") -> VISHNUPRIYA | J5: =IF($J$2=TRUE,SL!V3,"") -> VIDHYA | K5: =IF($K$2=TRUE,KOLUSU!V3,"") -> VIJI-2 | L5: =IF($L$2=TRUE,TEA!V3,"") -> SANTHIYA | M5: =IF($M$2=TRUE,MET.MKT!V3,"") -> DHANALAKSHMI | N5: =IF($N$2=TRUE,'SIL.ARR (MOR&EVE)'!V3,"") -> RAJI-2 | O5: =IF($O$2=TRUE,CHAIN!V3,"") -> JEYANTHI | P5: =IF($P$2=TRUE,'CHAIN ARR'!V3,"") -> MUTHUPRIYA | Q5: =IF($Q$2=TRUE,'DROPS ARR'!V3,"") -> SUDHARSHINI | S5: =E30 | T5: =E3 -> CASHIER | V5: =IF($V$2=TRUE,DROPS!V3,"") -> VIJI-2 | W5: =IF($W$2=TRUE,RING!V3,"") -> VIDHYA | X5: =IF($X$2=TRUE,'EVENING CLEAN'!V3,"") -> RAJI-1 | Y5: =IF($Y$2=TRUE,'DUSTBIN CHECK'!V3,"") -> BHARATHI | AA5: =Y31 -> BHARATHI | AB5: =Y3 -> DUSTBIN CHECK | AD5: =IF($AD$2=TRUE,'DUSTBIN CLEAN'!V3,"") -> VIJI-2 | AE5: =IF($AE$2=TRUE,'TRAY ARR'!V3,"") -> KAVIYA | AG5: =IF($AG$2=TRUE,'DOOR CLOSING'!V3,"") -> ARULMURUGAN | AH5: =IF(WEEKDAY(TODAY()+1)=1, "PARIMANAM",'DOOR OPEN'!V3) -> ARULMURUGAN | AI5: =IF($AI$2=TRUE,'MOR CLEAN'!X3,'MOR CLEAN'!V3) -> VIJI-1 | AK5: =F30 | AL5: =F29 -> STEPS | AN5: =IF($AN$2=TRUE,PURSE!X3,PURSE!V3) -> YAMUNA | AO5: =IF($AO$2=TRUE,'MAADI CLEAN'!X3,'MAADI CLEAN'!V3) -> RAJI-1 | AP5: =IF($AP$2=TRUE,'FAN CLEAN'!X3,'FAN CLEAN'!V3) -> VISHNUPRIYA
A6: =F30 | B6: =F3 -> STEPS | D6: =IF($D$2=TRUE,CHITTAI!V4,"") | E6: =IF($E$2=TRUE,CASH!V4,"") | F6: =IF($F$2=TRUE,STEPS!V4,"") | G6: =IF($G$2=TRUE,COLLECTION!V4,"") -> VIJI-1 | H6: =IF($H$2=TRUE,'PATHIRAM,SL BOX'!V4,"") -> VISHNUPRIYA | I6: =IF($I$2=TRUE,PATHIRAM!V4,"") -> YAMUNA | J6: =IF($J$2=TRUE,SL!V4,"") -> KAVIYA | K6: =IF($K$2=TRUE,KOLUSU!V4,"") -> BHARATHI | L6: =IF($L$2=TRUE,TEA!V4,"") -> BHARATHI | M6: =IF($M$2=TRUE,MET.MKT!V4,"") -> KAVIYA | N6: =IF($N$2=TRUE,'SIL.ARR (MOR&EVE)'!V4,"") -> SANTHIYA | O6: =IF($O$2=TRUE,CHAIN!V4,"") -> BHARATHI | P6: =IF($P$2=TRUE,'CHAIN ARR'!V4,"") -> SAHANA | Q6: =IF($Q$2=TRUE,'DROPS ARR'!V4,"") -> DEEPA | S6: =F30 | T6: =F3 -> STEPS | V6: =IF($V$2=TRUE,DROPS!V4,"") -> VIJI-1 | W6: =IF($W$2=TRUE,RING!V4,"") -> SUDHARSHINI | X6: =IF($X$2=TRUE,'EVENING CLEAN'!V4,"") -> SAHANA | Y6: =IF($Y$2=TRUE,'DUSTBIN CHECK'!V4,"") -> RAJI-2 | AA6: =D30 | AB6: =D29 -> CHITTAI | AD6: =IF($AD$2=TRUE,'DUSTBIN CLEAN'!V4,"") -> JEYANTHI | AE6: =IF($AE$2=TRUE,'TRAY ARR'!V4,"") -> RAJI-1 | AG6: =IF($AG$2=TRUE,'DOOR CLOSING'!V4,"") -> BALASUBRAMANI | AH6: =IF(WEEKDAY(TODAY()+1)=1, "PARIMANAM",'DOOR OPEN'!V4) -> KOLANCHIYAPPAN | AI6: =IF($AI$2=TRUE,'MOR CLEAN'!X4,'MOR CLEAN'!V4) -> VIJI-2 | AK6: =AI30 -> RANI | AL6: =AI3 -> MOR CLEAN | AN6: =IF($AN$2=TRUE,PURSE!X4,PURSE!V4) -> JEYANTHI | AO6: =IF($AO$2=TRUE,'MAADI CLEAN'!X4,'MAADI CLEAN'!V4) -> SAHANA | AP6: =IF($AP$2=TRUE,'FAN CLEAN'!X4,'FAN CLEAN'!V4) -> BHARATHI
A7: =G30 -> VIJI-2 | B7: =G3 -> COLLECTION | D7: =IF($D$2=TRUE,CHITTAI!V5,"") | E7: =IF($E$2=TRUE,CASH!V5,"") | F7: =IF($F$2=TRUE,STEPS!V5,"") | G7: =IF($G$2=TRUE,COLLECTION!V5,"") -> DEEPA | H7: =IF($H$2=TRUE,'PATHIRAM,SL BOX'!V5,"") -> RAJI-1 | I7: =IF($I$2=TRUE,PATHIRAM!V5,"") -> VIJI-2 | J7: =IF($J$2=TRUE,SL!V5,"") -> RAJI-2 | K7: =IF($K$2=TRUE,KOLUSU!V5,"") -> RAJI-1 | L7: =IF($L$2=TRUE,TEA!V5,"") -> PRIYANKA | M7: =IF($M$2=TRUE,MET.MKT!V5,"") -> CHINNAMMAL | N7: =IF($N$2=TRUE,'SIL.ARR (MOR&EVE)'!V5,"") -> SHANTHI | O7: =IF($O$2=TRUE,CHAIN!V5,"") -> SUDHARSHINI | P7: =IF($P$2=TRUE,'CHAIN ARR'!V5,"") -> VIDHYA | Q7: =IF($Q$2=TRUE,'DROPS ARR'!V5,"") -> VIJI-2 | S7: =L30 -> SANTHIYA | T7: =L3 -> TEA | V7: =IF($V$2=TRUE,DROPS!V5,"") -> BHARATHI | W7: =IF($W$2=TRUE,RING!V5,"") -> BHARATHI | X7: =IF($X$2=TRUE,'EVENING CLEAN'!V5,"") -> VIJI-1 | Y7: =IF($Y$2=TRUE,'DUSTBIN CHECK'!V5,"") -> MUTHUPRIYA | AA7: =E30 | AB7: =E29 -> CASHIER | AD7: =IF($AD$2=TRUE,'DUSTBIN CLEAN'!V5,"") -> RAJI-1 | AE7: =IF($AE$2=TRUE,'TRAY ARR'!V5,"") -> SUDHARSHINI | AG7: =IF($AG$2=TRUE,'DOOR CLOSING'!V5,"") -> PANDIKUMAR | AH7: =IF(WEEKDAY(TODAY()+1)=1, "PARIMANAM",'DOOR OPEN'!V5) -> PANDI-2 | AI7: =IF($AI$2=TRUE,'MOR CLEAN'!X5,'MOR CLEAN'!V5) -> BHARATHI | AK7: =AI31 -> VIJI-1 | AL7: =AI3 -> MOR CLEAN | AN7: =IF($AN$2=TRUE,PURSE!X5,PURSE!V5) -> NIVETHA | AO7: =IF($AO$2=TRUE,'MAADI CLEAN'!X5,'MAADI CLEAN'!V5) -> KAVIYA | AP7: =IF($AP$2=TRUE,'FAN CLEAN'!X5,'FAN CLEAN'!V5) -> RANI
A8: =H30 -> RAJI-2 | B8: =H3 -> PATHIRAM,SL BOX | D8: =IF($D$2=TRUE,CHITTAI!V6,"") | E8: =IF($E$2=TRUE,CASH!V6,"") | F8: =IF($F$2=TRUE,STEPS!V6,"") | G8: =IF($G$2=TRUE,COLLECTION!V6,"") -> DHANALAKSHMI | H8: =IF($H$2=TRUE,'PATHIRAM,SL BOX'!V6,"") -> YAMUNA | I8: =IF($I$2=TRUE,PATHIRAM!V6,"") -> RAJI-2 | J8: =IF($J$2=TRUE,SL!V6,"") -> VIJI-2 | K8: =IF($K$2=TRUE,KOLUSU!V6,"") -> JEYANTHI | L8: =IF($L$2=TRUE,TEA!V6,"") -> RANI | M8: =IF($M$2=TRUE,MET.MKT!V6,"") -> NIVETHA | N8: =IF($N$2=TRUE,'SIL.ARR (MOR&EVE)'!V6,"") -> KAVIYA | O8: =IF($O$2=TRUE,CHAIN!V6,"") -> NIVETHA | P8: =IF($P$2=TRUE,'CHAIN ARR'!V6,"") -> JEYANTHI | Q8: =IF($Q$2=TRUE,'DROPS ARR'!V6,"") -> VIJI-1 | S8: =L31 -> PRIYANKA | T8: =L3 -> TEA | V8: =IF($V$2=TRUE,DROPS!V6,"") -> RAJI-2 | W8: =IF($W$2=TRUE,RING!V6,"") -> DHANALAKSHMI | X8: =IF($X$2=TRUE,'EVENING CLEAN'!V6,"") -> BHARATHI | Y8: =IF($Y$2=TRUE,'DUSTBIN CHECK'!V6,"") -> SAHANA | AA8: =F30 | AB8: =F29 -> STEPS | AD8: =IF($AD$2=TRUE,'DUSTBIN CLEAN'!V6,"") -> RAJI-2 | AE8: =IF($AE$2=TRUE,'TRAY ARR'!V6,"") -> VIJI-2 | AG8: =IF($AG$2=TRUE,'DOOR CLOSING'!V6,"") -> SYED ABUTHAHIR | AH8: =IF(WEEKDAY(TODAY()+1)=1, "PARIMANAM",'DOOR OPEN'!V6) -> SAKTHIVEL 2 | AI8: =IF($AI$2=TRUE,'MOR CLEAN'!X6,'MOR CLEAN'!V6) -> SHANTHI | AK8: =AI32 -> VIJI-2 | AL8: =AI3 -> MOR CLEAN | AN8: =IF($AN$2=TRUE,PURSE!X6,PURSE!V6) -> RAJI-1 | AO8: =IF($AO$2=TRUE,'MAADI CLEAN'!X6,'MAADI CLEAN'!V6) -> RANI | AP8: =IF($AP$2=TRUE,'FAN CLEAN'!X6,'FAN CLEAN'!V6) -> NIVETHA
A9: =H31 -> VIJI-1 | B9: =H3 -> PATHIRAM,SL BOX | D9: =IF($D$2=TRUE,CHITTAI!V7,"") | E9: =IF($E$2=TRUE,CASH!V7,"") | F9: =IF($F$2=TRUE,STEPS!V7,"") | G9: =IF($G$2=TRUE,COLLECTION!V7,"") -> RAJI-1 | H9: =IF($H$2=TRUE,'PATHIRAM,SL BOX'!V7,"") -> CHINNAMMAL | I9: =IF($I$2=TRUE,PATHIRAM!V7,"") -> VIJI-1 | J9: =IF($J$2=TRUE,SL!V7,"") -> CHINNAMMAL | K9: =IF($K$2=TRUE,KOLUSU!V7,"") -> YAMUNA | L9: =IF($L$2=TRUE,TEA!V7,"") -> VIJI-2 | M9: =IF($M$2=TRUE,MET.MKT!V7,"") -> PRIYANKA | N9: =IF($N$2=TRUE,'SIL.ARR (MOR&EVE)'!V7,"") -> SUDHARSHINI | O9: =IF($O$2=TRUE,CHAIN!V7,"") -> DEEPA | P9: =IF($P$2=TRUE,'CHAIN ARR'!V7,"") -> SANTHIYA | Q9: =IF($Q$2=TRUE,'DROPS ARR'!V7,"") -> PRIYANKA | S9: =O30 -> NIVETHA | T9: =O3 -> CHAIN | V9: =IF($V$2=TRUE,DROPS!V7,"") -> DEEPA | W9: =IF($W$2=TRUE,RING!V7,"") -> YAMUNA | X9: =IF($X$2=TRUE,'EVENING CLEAN'!V7,"") -> SUDHARSHINI | Y9: =IF($Y$2=TRUE,'DUSTBIN CHECK'!V7,"") -> RANI | AA9: =P30 -> KAVIYA | AB9: =P3 -> CHAIN ARRANGE | AD9: =IF($AD$2=TRUE,'DUSTBIN CLEAN'!V7,"") -> VISHNUPRIYA | AE9: =IF($AE$2=TRUE,'TRAY ARR'!V7,"") -> YAMUNA | AK9: =AN30 -> CHINNAMMAL | AL9: =AN3 -> PURSE,BAG | AN9: =IF($AN$2=TRUE,PURSE!X7,PURSE!V7) -> VIJI-2 | AO9: =IF($AO$2=TRUE,'MAADI CLEAN'!X7,'MAADI CLEAN'!V7) -> VIJI-1 | AP9: =IF($AP$2=TRUE,'FAN CLEAN'!X7,'FAN CLEAN'!V7) -> PRIYANKA
A10: =I30 -> SAHANA | B10: =I3 -> PATHIRAM | D10: =IF($D$2=TRUE,CHITTAI!V8,"") | E10: =IF($E$2=TRUE,CASH!V8,"") | F10: =IF($F$2=TRUE,STEPS!V8,"") | G10: =IF($G$2=TRUE,COLLECTION!V8,"") | H10: =IF($H$2=TRUE,'PATHIRAM,SL BOX'!V8,"") -> SAHANA | I10: =IF($I$2=TRUE,PATHIRAM!V8,"") -> DEEPA | J10: =IF($J$2=TRUE,SL!V8,"") -> SHANTHI | K10: =IF($K$2=TRUE,KOLUSU!V8,"") -> MUTHUPRIYA | L10: =IF($L$2=TRUE,TEA!V8,"") -> VIJI-1 | M10: =IF($M$2=TRUE,MET.MKT!V8,"") -> YAMUNA | N10: =IF($N$2=TRUE,'SIL.ARR (MOR&EVE)'!V8,"") -> DEEPA | O10: =IF($O$2=TRUE,CHAIN!V8,"") -> SAHANA | P10: =IF($P$2=TRUE,'CHAIN ARR'!V8,"") -> SUDHARSHINI | Q10: =IF($Q$2=TRUE,'DROPS ARR'!V8,"") -> VISHNUPRIYA | S10: =V30 -> JEYANTHI | T10: =V3 -> DROPS | V10: =IF($V$2=TRUE,DROPS!V8,"") -> VISHNUPRIYA | W10: =IF($W$2=TRUE,RING!V8,"") -> VISHNUPRIYA | X10: =IF($X$2=TRUE,'EVENING CLEAN'!V8,"") -> RANI | Y10: =IF($Y$2=TRUE,'DUSTBIN CHECK'!V8,"") -> JEYANTHI | AA10: =Q30 -> SHANTHI | AB10: =Q3 -> DROPS ARRANGE | AD10: =IF($AD$2=TRUE,'DUSTBIN CLEAN'!V8,"") -> DEEPA | AE10: =IF($AE$2=TRUE,'TRAY ARR'!V8,"") -> VIJI-1 | AK10: =AN31 -> YAMUNA | AL10: =AN3 -> PURSE,BAG | AN10: =IF($AN$2=TRUE,PURSE!X8,PURSE!V8) -> DEEPA | AO10: =IF($AO$2=TRUE,'MAADI CLEAN'!X8,'MAADI CLEAN'!V8) -> CHINNAMMAL | AP10: =IF($AP$2=TRUE,'FAN CLEAN'!X8,'FAN CLEAN'!V8) -> VIDHYA
A11: =I31 -> VISHNUPRIYA | B11: =I3 -> PATHIRAM | D11: =IF($D$2=TRUE,CHITTAI!V9,"") | E11: =IF($E$2=TRUE,CASH!V9,"") | F11: =IF($F$2=TRUE,STEPS!V9,"") | G11: =IF($G$2=TRUE,COLLECTION!V9,"") | H11: =IF($H$2=TRUE,'PATHIRAM,SL BOX'!V9,"") -> SUDHARSHINI | I11: =IF($I$2=TRUE,PATHIRAM!V9,"") -> KAVIYA | J11: =IF($J$2=TRUE,SL!V9,"") -> NIVETHA | K11: =IF($K$2=TRUE,KOLUSU!V9,"") -> SAHANA | L11: =IF($L$2=TRUE,TEA!V9,"") -> DHANALAKSHMI | M11: =IF($M$2=TRUE,MET.MKT!V9,"") -> RAJI-1 | N11: =IF($N$2=TRUE,'SIL.ARR (MOR&EVE)'!V9,"") -> PRIYANKA | O11: =IF($O$2=TRUE,CHAIN!V9,"") -> DHANALAKSHMI | P11: =IF($P$2=TRUE,'CHAIN ARR'!V9,"") -> DEEPA | Q11: =IF($Q$2=TRUE,'DROPS ARR'!V9,"") -> KAVIYA | S11: =W30 -> CHINNAMMAL | T11: =W3 -> RING | V11: =IF($V$2=TRUE,DROPS!V9,"") -> DHANALAKSHMI | W11: =IF($W$2=TRUE,RING!V9,"") -> VIJI-1 | X11: =IF($X$2=TRUE,'EVENING CLEAN'!V9,"") -> NIVETHA | Y11: =IF($Y$2=TRUE,'DUSTBIN CHECK'!V9,"") -> YAMUNA | AA11: =Q31 -> VIJI-2 | AB11: =Q3 -> DROPS ARRANGE | AD11: =IF($AD$2=TRUE,'DUSTBIN CLEAN'!V9,"") -> CHINNAMMAL | AE11: =IF($AE$2=TRUE,'TRAY ARR'!V9,"") -> VISHNUPRIYA | AK11: =AO30 -> VIDHYA | AL11: =AO3 -> MAADI CLEAN | AN11: =IF($AN$2=TRUE,PURSE!X9,PURSE!V9) -> MUTHUPRIYA | AO11: =IF($AO$2=TRUE,'MAADI CLEAN'!X9,'MAADI CLEAN'!V9) -> JEYANTHI | AP11: =IF($AP$2=TRUE,'FAN CLEAN'!X9,'FAN CLEAN'!V9) -> DEEPA
A12: =J30 -> SUDHARSHINI | B12: =J3 -> SL | D12: =IF($D$2=TRUE,CHITTAI!V10,"") | E12: =IF($E$2=TRUE,CASH!V10,"") | F12: =IF($F$2=TRUE,STEPS!V10,"") | G12: =IF($G$2=TRUE,COLLECTION!V10,"") | H12: =IF($H$2=TRUE,'PATHIRAM,SL BOX'!V10,"") -> JEYANTHI | I12: =IF($I$2=TRUE,PATHIRAM!V10,"") -> MUTHUPRIYA | J12: =IF($J$2=TRUE,SL!V10,"") -> RAJI-1 | K12: =IF($K$2=TRUE,KOLUSU!V10,"") -> SANTHIYA | L12: =IF($L$2=TRUE,TEA!V10,"") -> NIVETHA | M12: =IF($M$2=TRUE,MET.MKT!V10,"") -> SHANTHI | N12: =IF($N$2=TRUE,'SIL.ARR (MOR&EVE)'!V10,"") -> RANI | O12: =IF($O$2=TRUE,CHAIN!V10,"") -> YAMUNA | P12: =IF($P$2=TRUE,'CHAIN ARR'!V10,"") -> PRIYANKA | Q12: =IF($Q$2=TRUE,'DROPS ARR'!V10,"") -> RAJI-1 | S12: =X30 -> RAJI-1 | T12: =X3 -> EVENING CLEANING | V12: =IF($V$2=TRUE,DROPS!V10,"") -> SUDHARSHINI | W12: =IF($W$2=TRUE,RING!V10,"") -> DEEPA | X12: =IF($X$2=TRUE,'EVENING CLEAN'!V10,"") -> CHINNAMMAL | Y12: =IF($Y$2=TRUE,'DUSTBIN CHECK'!V10,"") -> KAVIYA | AA12: =AD30 -> SANTHIYA | AB12: =AD3 -> DUSTBIN CLEAN | AD12: =IF($AD$2=TRUE,'DUSTBIN CLEAN'!V10,"") -> SUDHARSHINI | AE12: =IF($AE$2=TRUE,'TRAY ARR'!V10,"") -> DHANALAKSHMI | AK12: =AO31 -> RAJI-1 | AL12: =AO3 -> MAADI CLEAN | AN12: =IF($AN$2=TRUE,PURSE!X10,PURSE!V10) -> SANTHIYA | AO12: =IF($AO$2=TRUE,'MAADI CLEAN'!X10,'MAADI CLEAN'!V10) -> PANJU | AP12: =IF($AP$2=TRUE,'FAN CLEAN'!X10,'FAN CLEAN'!V10) -> PANJU
A13: =J31 -> VIDHYA | B13: =J3 -> SL | D13: =IF($D$2=TRUE,CHITTAI!V11,"") | E13: =IF($E$2=TRUE,CASH!V11,"") | F13: =IF($F$2=TRUE,STEPS!V11,"") | G13: =IF($G$2=TRUE,COLLECTION!V11,"") | H13: =IF($H$2=TRUE,'PATHIRAM,SL BOX'!V11,"") -> KAVIYA | I13: =IF($I$2=TRUE,PATHIRAM!V11,"") -> SANTHIYA | J13: =IF($J$2=TRUE,SL!V11,"") -> BHARATHI | K13: =IF($K$2=TRUE,KOLUSU!V11,"") -> DHANALAKSHMI | L13: =IF($L$2=TRUE,TEA!V11,"") -> MUTHUPRIYA | M13: =IF($M$2=TRUE,MET.MKT!V11,"") -> SANTHIYA | N13: =IF($N$2=TRUE,'SIL.ARR (MOR&EVE)'!V11,"") -> VIJI-1 | O13: =IF($O$2=TRUE,CHAIN!V11,"") -> VISHNUPRIYA | P13: =IF($P$2=TRUE,'CHAIN ARR'!V11,"") -> VIJI-2 | Q13: =IF($Q$2=TRUE,'DROPS ARR'!V11,"") -> JEYANTHI | S13: =Y30 -> VIJI-2 | T13: =Y3 -> DUSTBIN CHECK | V13: =IF($V$2=TRUE,DROPS!V11,"") -> MUTHUPRIYA | W13: =IF($W$2=TRUE,RING!V11,"") -> NIVETHA | X13: =IF($X$2=TRUE,'EVENING CLEAN'!V11,"") -> MUTHUPRIYA | Y13: =IF($Y$2=TRUE,'DUSTBIN CHECK'!V11,"") -> VISHNUPRIYA | AA13: =AD31 -> JEYANTHI | AB13: =AD3 -> DUSTBIN CLEAN | AD13: =IF($AD$2=TRUE,'DUSTBIN CLEAN'!V11,"") -> PANJU | AE13: =IF($AE$2=TRUE,'TRAY ARR'!V11,"") -> SHANTHI | AK13: =AO32 -> SAHANA | AL13: =AO3 -> MAADI CLEAN | AN13: =IF($AN$2=TRUE,PURSE!X11,PURSE!V11) -> RAJI-2 | AO13: =IF($AO$2=TRUE,'MAADI CLEAN'!X11,'MAADI CLEAN'!V11) -> DEEPA | AP13: =IF($AP$2=TRUE,'FAN CLEAN'!X11,'FAN CLEAN'!V11) -> KAVIYA
A14: =K30 -> DEEPA | B14: =K3 -> KOLUSU | D14: =IF($D$2=TRUE,CHITTAI!V12,"") | E14: =IF($E$2=TRUE,CASH!V12,"") | F14: =IF($F$2=TRUE,STEPS!V12,"") | G14: =IF($G$2=TRUE,COLLECTION!V12,"") | H14: =IF($H$2=TRUE,'PATHIRAM,SL BOX'!V12,"") -> MUTHUPRIYA | I14: =IF($I$2=TRUE,PATHIRAM!V12,"") -> NIVETHA | J14: =IF($J$2=TRUE,SL!V12,"") -> YAMUNA | K14: =IF($K$2=TRUE,KOLUSU!V12,"") -> VIDHYA | L14: =IF($L$2=TRUE,TEA!V12,"") -> PANJU | M14: =IF($M$2=TRUE,MET.MKT!V12,"") -> VISHNUPRIYA | N14: =IF($N$2=TRUE,'SIL.ARR (MOR&EVE)'!V12,"") -> RAJI-1 | O14: =IF($O$2=TRUE,CHAIN!V12,"") -> VIJI-2 | P14: =IF($P$2=TRUE,'CHAIN ARR'!V12,"") -> RAJI-1 | Q14: =IF($Q$2=TRUE,'DROPS ARR'!V12,"") -> VIDHYA | S14: =Y31 -> BHARATHI | T14: =Y3 -> DUSTBIN CHECK | V14: =IF($V$2=TRUE,DROPS!V12,"") -> SAHANA | W14: =IF($W$2=TRUE,RING!V12,"") -> MUTHUPRIYA | X14: =IF($X$2=TRUE,'EVENING CLEAN'!V12,"") -> RAJI-2 | Y14: =IF($Y$2=TRUE,'DUSTBIN CHECK'!V12,"") -> PANJU | AD14: =IF($AD$2=TRUE,'DUSTBIN CLEAN'!V12,"") -> SHANTHI | AE14: =IF($AE$2=TRUE,'TRAY ARR'!V12,"") -> JEYANTHI | AK14: =AO33 -> KAVIYA | AL14: =AO3 -> MAADI CLEAN | AN14: =IF($AN$2=TRUE,PURSE!X12,PURSE!V12) -> KAVIYA | AO14: =IF($AO$2=TRUE,'MAADI CLEAN'!X12,'MAADI CLEAN'!V12) -> DHANALAKSHMI | AP14: =IF($AP$2=TRUE,'FAN CLEAN'!X12,'FAN CLEAN'!V12) -> YAMUNA
A15: =K31 -> BHARATHI | B15: =K3 -> KOLUSU | D15: =IF($D$2=TRUE,CHITTAI!V13,"") | E15: =IF($E$2=TRUE,CASH!V13,"") | F15: =IF($F$2=TRUE,STEPS!V14,"") | G15: =IF($G$2=TRUE,COLLECTION!V13,"") | H15: =IF($H$2=TRUE,'PATHIRAM,SL BOX'!V13,"") -> RANI | I15: =IF($I$2=TRUE,PATHIRAM!V13,"") -> PRIYANKA | J15: =IF($J$2=TRUE,SL!V13,"") -> DHANALAKSHMI | K15: =IF($K$2=TRUE,KOLUSU!V13,"") -> VIJI-1 | L15: =IF($L$2=TRUE,TEA!V13,"") -> SHANTHI | M15: =IF($M$2=TRUE,MET.MKT!V13,"") -> DEEPA | N15: =IF($N$2=TRUE,'SIL.ARR (MOR&EVE)'!V13,"") -> NIVETHA | O15: =IF($O$2=TRUE,CHAIN!V13,"") -> RAJI-1 | P15: =IF($P$2=TRUE,'CHAIN ARR'!V13,"") -> RAJI-2 | Q15: =IF($Q$2=TRUE,'DROPS ARR'!V13,"") -> SAHANA | V15: =IF($V$2=TRUE,DROPS!V13,"") -> NIVETHA | W15: =IF($W$2=TRUE,RING!V13,"") -> JEYANTHI | X15: =IF($X$2=TRUE,'EVENING CLEAN'!V13,"") -> VIJI-2 | Y15: =IF($Y$2=TRUE,'DUSTBIN CHECK'!V13,"") -> VIJI-1 | AD15: =IF($AD$2=TRUE,'DUSTBIN CLEAN'!V13,"") -> KAVIYA | AE15: =IF($AE$2=TRUE,'TRAY ARR'!V13,"") -> SANTHIYA | AN15: =IF($AN$2=TRUE,PURSE!X13,PURSE!V13) -> SHANTHI | AO15: =IF($AO$2=TRUE,'MAADI CLEAN'!X13,'MAADI CLEAN'!V13) -> RAJI-2 | AP15: =IF($AP$2=TRUE,'FAN CLEAN'!X13,'FAN CLEAN'!V13) -> RAJI-1
A16: =K32 -> RAJI-1 | B16: =K3 -> KOLUSU | D16: =IF($D$2=TRUE,CHITTAI!V14,"") | E16: =IF($E$2=TRUE,CASH!V14,"") | F16: =IF($F$2=TRUE,#REF!,"") | G16: =IF($G$2=TRUE,COLLECTION!V14,"") | H16: =IF($H$2=TRUE,'PATHIRAM,SL BOX'!V14,"") -> SANTHIYA | I16: =IF($I$2=TRUE,PATHIRAM!V14,"") -> DHANALAKSHMI | J16: =IF($J$2=TRUE,SL!V14,"") -> MUTHUPRIYA | K16: =IF($K$2=TRUE,KOLUSU!V14,"") -> PRIYANKA | L16: =IF($L$2=TRUE,TEA!V14,"") -> VIDHYA | M16: =IF($M$2=TRUE,MET.MKT!V14,"") -> VIDHYA | N16: =IF($N$2=TRUE,'SIL.ARR (MOR&EVE)'!V14,"") -> PANJU | O16: =IF($O$2=TRUE,CHAIN!V14,"") -> VIDHYA | P16: =IF($P$2=TRUE,'CHAIN ARR'!V14,"") -> CHINNAMMAL | Q16: =IF($Q$2=TRUE,'DROPS ARR'!V14,"") -> NIVETHA | V16: =IF($V$2=TRUE,DROPS!V14,"") -> CHINNAMMAL | W16: =IF($W$2=TRUE,RING!V14,"") -> RAJI-1 | X16: =IF($X$2=TRUE,'EVENING CLEAN'!V14,"") -> JEYANTHI | Y16: =IF($Y$2=TRUE,'DUSTBIN CHECK'!V14,"") -> DHANALAKSHMI | AD16: =IF($AD$2=TRUE,'DUSTBIN CLEAN'!V14,"") -> YAMUNA | AE16: =IF($AE$2=TRUE,'TRAY ARR'!V14,"") -> PRIYANKA | AN16: =IF($AN$2=TRUE,PURSE!X14,PURSE!V14) -> PRIYANKA | AO16: =IF($AO$2=TRUE,'MAADI CLEAN'!X14,'MAADI CLEAN'!V14) -> SUDHARSHINI | AP16: =IF($AP$2=TRUE,'FAN CLEAN'!X14,'FAN CLEAN'!V14) -> SANTHIYA
A17: =K33 -> JEYANTHI | B17: =K3 -> KOLUSU | D17: =IF($D$2=TRUE,CHITTAI!V15,"") | E17: =IF($E$2=TRUE,CASH!V15,"") | F17: =IF($F$2=TRUE,STEPS!V15,"") | G17: =IF($G$2=TRUE,COLLECTION!V15,"") | H17: =IF($H$2=TRUE,'PATHIRAM,SL BOX'!V15,"") -> SHANTHI | I17: =IF($I$2=TRUE,PATHIRAM!V15,"") -> JEYANTHI | J17: =IF($J$2=TRUE,SL!V15,"") -> SANTHIYA | K17: =IF($K$2=TRUE,KOLUSU!V15,"") -> RAJI-2 | L17: =IF($L$2=TRUE,TEA!V15,"") -> SAHANA | M17: =IF($M$2=TRUE,MET.MKT!V15,"") -> MUTHUPRIYA | N17: =IF($N$2=TRUE,'SIL.ARR (MOR&EVE)'!V15,"") -> BHARATHI | O17: =IF($O$2=TRUE,CHAIN!V15,"") -> VIJI-1 | P17: =IF($P$2=TRUE,'CHAIN ARR'!V15,"") -> DHANALAKSHMI | Q17: =IF($Q$2=TRUE,'DROPS ARR'!V15,"") -> SANTHIYA | V17: =IF($V$2=TRUE,DROPS!V15,"") -> VIDHYA | W17: =IF($W$2=TRUE,RING!V15,"") -> SAHANA | X17: =IF($X$2=TRUE,'EVENING CLEAN'!V15,"") -> PANJU | Y17: =IF($Y$2=TRUE,'DUSTBIN CHECK'!V15,"") -> SHANTHI | AD17: =IF($AD$2=TRUE,'DUSTBIN CLEAN'!V15,"") -> RANI | AE17: =IF($AE$2=TRUE,'TRAY ARR'!V15,"") -> VIDHYA | AN17: =IF($AN$2=TRUE,PURSE!X15,PURSE!V15) -> RANI | AO17: =IF($AO$2=TRUE,'MAADI CLEAN'!X15,'MAADI CLEAN'!V15) -> MUTHUPRIYA | AP17: =IF($AP$2=TRUE,'FAN CLEAN'!X15,'FAN CLEAN'!V15) -> SAHANA
A18: =L30 -> SANTHIYA | B18: =L3 -> TEA | D18: =IF($D$2=TRUE,CHITTAI!V16,"") | E18: =IF($E$2=TRUE,CASH!V16,"") | F18: =IF($F$2=TRUE,STEPS!V16,"") | G18: =IF($G$2=TRUE,COLLECTION!V16,"") | H18: =IF($H$2=TRUE,'PATHIRAM,SL BOX'!V16,"") -> DEEPA | I18: =IF($I$2=TRUE,PATHIRAM!V16,"") -> RAJI-1 | J18: =IF($J$2=TRUE,SL!V16,"") -> PRIYANKA | K18: =IF($K$2=TRUE,KOLUSU!V16,"") -> SHANTHI | L18: =IF($L$2=TRUE,TEA!V16,"") -> VISHNUPRIYA | M18: =IF($M$2=TRUE,MET.MKT!V16,"") -> VIJI-1 | N18: =IF($N$2=TRUE,'SIL.ARR (MOR&EVE)'!V16,"") -> VIDHYA | O18: =IF($O$2=TRUE,CHAIN!V16,"") -> MUTHUPRIYA | P18: =IF($P$2=TRUE,'CHAIN ARR'!V16,"") -> BHARATHI | Q18: =IF($Q$2=TRUE,'DROPS ARR'!V16,"") -> DHANALAKSHMI | V18: =IF($V$2=TRUE,DROPS!V16,"") -> RAJI-1 | W18: =IF($W$2=TRUE,RING!V16,"") -> VIJI-2 | X18: =IF($X$2=TRUE,'EVENING CLEAN'!V16,"") -> VISHNUPRIYA | Y18: =IF($Y$2=TRUE,'DUSTBIN CHECK'!V16,"") -> CHINNAMMAL | AD18: =IF($AD$2=TRUE,'DUSTBIN CLEAN'!V16,"") -> VIDHYA | AE18: =IF($AE$2=TRUE,'TRAY ARR'!V16,"") -> BHARATHI | AN18: =IF($AN$2=TRUE,PURSE!X16,PURSE!V16) -> SUDHARSHINI | AO18: =IF($AO$2=TRUE,'MAADI CLEAN'!X16,'MAADI CLEAN'!V16) -> SANTHIYA | AP18: =IF($AP$2=TRUE,'FAN CLEAN'!X16,'FAN CLEAN'!V16) -> CHINNAMMAL
A19: =L31 -> PRIYANKA | B19: =L3 -> TEA | D19: =IF($D$2=TRUE,CHITTAI!V17,"") | E19: =IF($E$2=TRUE,CASH!V17,"") | F19: =IF($F$2=TRUE,STEPS!V17,"") | G19: =IF($G$2=TRUE,COLLECTION!V17,"") | H19: =IF($H$2=TRUE,'PATHIRAM,SL BOX'!V17,"") | I19: =IF($I$2=TRUE,PATHIRAM!V17,"") | J19: =IF($J$2=TRUE,SL!V17,"") | K19: =IF($K$2=TRUE,KOLUSU!V17,"") | L19: =IF($L$2=TRUE,TEA!V17,"") | M19: =IF($M$2=TRUE,MET.MKT!V17,"") | N19: =IF($N$2=TRUE,'SIL.ARR (MOR&EVE)'!V17,"") | O19: =IF($O$2=TRUE,CHAIN!V17,"") | P19: =IF($P$2=TRUE,'CHAIN ARR'!V17,"") -> SHANTHI | Q19: =IF($Q$2=TRUE,'DROPS ARR'!V17,"") | V19: =IF($V$2=TRUE,DROPS!V17,"") | W19: =IF($W$2=TRUE,RING!V17,"") | X19: =IF($X$2=TRUE,'EVENING CLEAN'!V17,"") | Y19: =IF($Y$2=TRUE,'DUSTBIN CHECK'!V17,"") | AD19: =IF($AD$2=TRUE,'DUSTBIN CLEAN'!V17,"") | AE19: =IF($AE$2=TRUE,'TRAY ARR'!V17,"") | AN19: =IF($AN$2=TRUE,PURSE!X17,PURSE!V17) | AO19: =IF($AO$2=TRUE,'MAADI CLEAN'!X17,'MAADI CLEAN'!V17) | AP19: =IF($AP$2=TRUE,'FAN CLEAN'!X17,'FAN CLEAN'!V17)
A20: =M30 -> DHANALAKSHMI | B20: =M3 -> MET.MKT | D20: =IF($D$2=TRUE,CHITTAI!V18,"") | E20: =IF($E$2=TRUE,CASH!V18,"") | F20: =IF($F$2=TRUE,STEPS!V18,"") | G20: =IF($G$2=TRUE,COLLECTION!V18,"") | H20: =IF($H$2=TRUE,'PATHIRAM,SL BOX'!V18,"") | I20: =IF($I$2=TRUE,PATHIRAM!V18,"") | J20: =IF($J$2=TRUE,SL!V18,"") | K20: =IF($K$2=TRUE,KOLUSU!V18,"") | L20: =IF($L$2=TRUE,TEA!V18,"") | M20: =IF($M$2=TRUE,MET.MKT!V18,"") | N20: =IF($N$2=TRUE,'SIL.ARR (MOR&EVE)'!V18,"") | O20: =IF($O$2=TRUE,CHAIN!V18,"") | P20: =IF($P$2=TRUE,'CHAIN ARR'!V18,"") -> NIVETHA | Q20: =IF($Q$2=TRUE,'DROPS ARR'!V18,"") | V20: =IF($V$2=TRUE,DROPS!V18,"") | W20: =IF($W$2=TRUE,RING!V18,"") | X20: =IF($X$2=TRUE,'EVENING CLEAN'!V18,"") | Y20: =IF($Y$2=TRUE,'DUSTBIN CHECK'!V18,"") | AD20: =IF($AD$2=TRUE,'DUSTBIN CLEAN'!V18,"") | AE20: =IF($AE$2=TRUE,'TRAY ARR'!V18,"") | AN20: =IF($AN$2=TRUE,PURSE!X18,PURSE!V18) | AO20: =IF($AO$2=TRUE,'MAADI CLEAN'!X18,'MAADI CLEAN'!V18) | AP20: =IF($AP$2=TRUE,'FAN CLEAN'!X18,'FAN CLEAN'!V18)
A21: =N30 -> CHINNAMMAL | B21: =N3 -> SIL.ARR (MOR&EVE) | D21: =IF($D$2=TRUE,CHITTAI!V19,"") | E21: =IF($E$2=TRUE,CASH!V19,"") | F21: =IF($F$2=TRUE,STEPS!V19,"") | G21: =IF($G$2=TRUE,COLLECTION!V19,"") | H21: =IF($H$2=TRUE,'PATHIRAM,SL BOX'!V19,"") | I21: =IF($I$2=TRUE,PATHIRAM!V19,"") | J21: =IF($J$2=TRUE,SL!V19,"") | K21: =IF($K$2=TRUE,KOLUSU!V19,"") | L21: =IF($L$2=TRUE,TEA!V19,"") | M21: =IF($M$2=TRUE,MET.MKT!V19,"") | N21: =IF($N$2=TRUE,'SIL.ARR (MOR&EVE)'!V19,"") | O21: =IF($O$2=TRUE,CHAIN!V19,"") | P21: =IF($P$2=TRUE,'CHAIN ARR'!V19,"") -> VISHNUPRIYA | Q21: =IF($Q$2=TRUE,'DROPS ARR'!V19,"") | V21: =IF($V$2=TRUE,DROPS!V19,"") | W21: =IF($W$2=TRUE,RING!V19,"") | X21: =IF($X$2=TRUE,'EVENING CLEAN'!V19,"") | Y21: =IF($Y$2=TRUE,'DUSTBIN CHECK'!V19,"") | AD21: =IF($AD$2=TRUE,'DUSTBIN CLEAN'!V19,"") | AE21: =IF($AE$2=TRUE,'TRAY ARR'!V19,"") | AN21: =IF($AN$2=TRUE,PURSE!X19,PURSE!V19) | AO21: =IF($AO$2=TRUE,'MAADI CLEAN'!X19,'MAADI CLEAN'!V19) | AP21: =IF($AP$2=TRUE,'FAN CLEAN'!X19,'FAN CLEAN'!V19)
A22: =N31 -> SHANTHI | B22: =N3 -> SIL.ARR (MOR&EVE) | D22: =IF($D$2=TRUE,CHITTAI!V20,"") | E22: =IF($E$2=TRUE,CASH!V20,"") | F22: =IF($F$2=TRUE,STEPS!V20,"") | G22: =IF($G$2=TRUE,COLLECTION!V20,"") | H22: =IF($H$2=TRUE,'PATHIRAM,SL BOX'!V20,"") | I22: =IF($I$2=TRUE,PATHIRAM!V20,"") | J22: =IF($J$2=TRUE,SL!V20,"") | K22: =IF($K$2=TRUE,KOLUSU!V20,"") | L22: =IF($L$2=TRUE,TEA!V20,"") | M22: =IF($M$2=TRUE,MET.MKT!V20,"") | N22: =IF($N$2=TRUE,'SIL.ARR (MOR&EVE)'!V20,"") | O22: =IF($O$2=TRUE,CHAIN!V20,"") | P22: =IF($P$2=TRUE,'CHAIN ARR'!V20,"") -> VIJI-1 | Q22: =IF($Q$2=TRUE,'DROPS ARR'!V20,"") | V22: =IF($V$2=TRUE,DROPS!V20,"") | W22: =IF($W$2=TRUE,RING!V20,"") | X22: =IF($X$2=TRUE,'EVENING CLEAN'!V20,"") | Y22: =IF($Y$2=TRUE,'DUSTBIN CHECK'!V20,"") | AD22: =IF($AD$2=TRUE,'DUSTBIN CLEAN'!V20,"") | AE22: =IF($AE$2=TRUE,'TRAY ARR'!V20,"") | AN22: =IF($AN$2=TRUE,PURSE!X20,PURSE!V20) | AO22: =IF($AO$2=TRUE,'MAADI CLEAN'!X20,'MAADI CLEAN'!V20) | AP22: =IF($AP$2=TRUE,'FAN CLEAN'!X20,'FAN CLEAN'!V20)
A23: =O30 -> NIVETHA | B23: =O3 -> CHAIN | D23: =IF($D$2=TRUE,CHITTAI!V21,"") | E23: =IF($E$2=TRUE,CASH!V21,"") | F23: =IF($F$2=TRUE,STEPS!V21,"") | G23: =IF($G$2=TRUE,COLLECTION!V21,"") | H23: =IF($H$2=TRUE,'PATHIRAM,SL BOX'!V21,"") | I23: =IF($I$2=TRUE,PATHIRAM!V21,"") | J23: =IF($J$2=TRUE,SL!V21,"") | K23: =IF($K$2=TRUE,KOLUSU!V21,"") | L23: =IF($L$2=TRUE,TEA!V21,"") | M23: =IF($M$2=TRUE,MET.MKT!V21,"") | N23: =IF($N$2=TRUE,'SIL.ARR (MOR&EVE)'!V21,"") | O23: =IF($O$2=TRUE,CHAIN!V21,"") | P23: =IF($P$2=TRUE,'CHAIN ARR'!V21,"") | Q23: =IF($Q$2=TRUE,'DROPS ARR'!V21,"") | V23: =IF($V$2=TRUE,DROPS!V21,"") | W23: =IF($W$2=TRUE,RING!V21,"") | X23: =IF($X$2=TRUE,'EVENING CLEAN'!V21,"") | Y23: =IF($Y$2=TRUE,'DUSTBIN CHECK'!V21,"") | AD23: =IF($AD$2=TRUE,'DUSTBIN CLEAN'!V21,"") | AE23: =IF($AE$2=TRUE,'TRAY ARR'!V21,"") | AN23: =IF($AN$2=TRUE,PURSE!X21,PURSE!V21) | AO23: =IF($AO$2=TRUE,'MAADI CLEAN'!X21,'MAADI CLEAN'!V21) | AP23: =IF($AP$2=TRUE,'FAN CLEAN'!X21,'FAN CLEAN'!V21)
A24: =P30 -> KAVIYA | B24: =P3 -> CHAIN ARRANGE | D24: =IF($D$2=TRUE,CHITTAI!V22,"") | E24: =IF($E$2=TRUE,CASH!V22,"") | F24: =IF($F$2=TRUE,STEPS!V22,"") | G24: =IF($G$2=TRUE,COLLECTION!V22,"") | H24: =IF($H$2=TRUE,'PATHIRAM,SL BOX'!V22,"") | I24: =IF($I$2=TRUE,PATHIRAM!V22,"") | J24: =IF($J$2=TRUE,SL!V22,"") | K24: =IF($K$2=TRUE,KOLUSU!V22,"") | L24: =IF($L$2=TRUE,TEA!V22,"") | M24: =IF($M$2=TRUE,MET.MKT!V22,"") | N24: =IF($N$2=TRUE,'SIL.ARR (MOR&EVE)'!V22,"") | O24: =IF($O$2=TRUE,CHAIN!V22,"") | P24: =IF($P$2=TRUE,'CHAIN ARR'!V22,"") | Q24: =IF($Q$2=TRUE,'DROPS ARR'!V22,"") | V24: =IF($V$2=TRUE,DROPS!V22,"") | W24: =IF($W$2=TRUE,RING!V22,"") | X24: =IF($X$2=TRUE,'EVENING CLEAN'!V22,"") | Y24: =IF($Y$2=TRUE,'DUSTBIN CHECK'!V22,"") | AD24: =IF($AD$2=TRUE,'DUSTBIN CLEAN'!V22,"") | AE24: =IF($AE$2=TRUE,'TRAY ARR'!V22,"") | AN24: =IF($AN$2=TRUE,PURSE!X22,PURSE!V22) | AO24: =IF($AO$2=TRUE,'MAADI CLEAN'!X22,'MAADI CLEAN'!V22) | AP24: =IF($AP$2=TRUE,'FAN CLEAN'!X22,'FAN CLEAN'!V22)
D25: =IF($D$2=TRUE,CHITTAI!V23,"") | E25: =IF($E$2=TRUE,CASH!V23,"") | F25: =IF($F$2=TRUE,STEPS!V23,"") | G25: =IF($G$2=TRUE,COLLECTION!V23,"") | H25: =IF($H$2=TRUE,'PATHIRAM,SL BOX'!V23,"") | I25: =IF($I$2=TRUE,PATHIRAM!V23,"") | J25: =IF($J$2=TRUE,SL!V23,"") | K25: =IF($K$2=TRUE,KOLUSU!V23,"") | L25: =IF($L$2=TRUE,TEA!V23,"") | M25: =IF($M$2=TRUE,MET.MKT!V23,"") | N25: =IF($N$2=TRUE,'SIL.ARR (MOR&EVE)'!V23,"") | O25: =IF($O$2=TRUE,CHAIN!V23,"") | P25: =IF($P$2=TRUE,'CHAIN ARR'!V23,"") | Q25: =IF($Q$2=TRUE,'DROPS ARR'!V23,"") | V25: =IF($V$2=TRUE,DROPS!V23,"") | W25: =IF($W$2=TRUE,RING!V23,"") | X25: =IF($X$2=TRUE,'EVENING CLEAN'!V23,"") | Y25: =IF($Y$2=TRUE,'DUSTBIN CHECK'!V23,"") | AD25: =IF($AD$2=TRUE,'DUSTBIN CLEAN'!V23,"") | AE25: =IF($AE$2=TRUE,'TRAY ARR'!V23,"") | AN25: =IF($AN$2=TRUE,PURSE!X23,PURSE!V23) | AO25: =IF($AO$2=TRUE,'MAADI CLEAN'!X23,'MAADI CLEAN'!V23) | AP25: =IF($AP$2=TRUE,'FAN CLEAN'!X23,'FAN CLEAN'!V23)
D26: =IF($D$2=TRUE,CHITTAI!V24,"") | E26: =IF($E$2=TRUE,CASH!V24,"") | F26: =IF($F$2=TRUE,STEPS!V24,"") | G26: =IF($G$2=TRUE,COLLECTION!V24,"") | H26: =IF($H$2=TRUE,'PATHIRAM,SL BOX'!V24,"") | I26: =IF($I$2=TRUE,PATHIRAM!V24,"") | J26: =IF($J$2=TRUE,SL!V24,"") | K26: =IF($K$2=TRUE,KOLUSU!V24,"") | L26: =IF($L$2=TRUE,TEA!V24,"") | M26: =IF($M$2=TRUE,MET.MKT!V24,"") | N26: =IF($N$2=TRUE,'SIL.ARR (MOR&EVE)'!V24,"") | O26: =IF($O$2=TRUE,CHAIN!V24,"") | P26: =IF($P$2=TRUE,'CHAIN ARR'!V24,"") | Q26: =IF($Q$2=TRUE,'DROPS ARR'!V24,"") | V26: =IF($V$2=TRUE,DROPS!V24,"") | W26: =IF($W$2=TRUE,RING!V24,"") | X26: =IF($X$2=TRUE,'EVENING CLEAN'!V24,"") | Y26: =IF($Y$2=TRUE,'DUSTBIN CHECK'!V24,"") | AD26: =IF($AD$2=TRUE,'DUSTBIN CLEAN'!V24,"") | AE26: =IF($AE$2=TRUE,'TRAY ARR'!V24,"") | AN26: =IF($AN$2=TRUE,PURSE!X24,PURSE!V24) | AO26: =IF($AO$2=TRUE,'MAADI CLEAN'!X24,'MAADI CLEAN'!V24) | AP26: =IF($AP$2=TRUE,'FAN CLEAN'!X24,'FAN CLEAN'!V24)
D27: =IF($D$2=TRUE,CHITTAI!V25,"") | E27: =IF($E$2=TRUE,CASH!V25,"") | F27: =IF($F$2=TRUE,STEPS!V25,"") | G27: =IF($G$2=TRUE,COLLECTION!V25,"") | H27: =IF($H$2=TRUE,'PATHIRAM,SL BOX'!V25,"") | I27: =IF($I$2=TRUE,PATHIRAM!V25,"") | J27: =IF($J$2=TRUE,SL!V25,"") | K27: =IF($K$2=TRUE,KOLUSU!V25,"") | L27: =IF($L$2=TRUE,TEA!V25,"") | M27: =IF($M$2=TRUE,MET.MKT!V25,"") | N27: =IF($N$2=TRUE,'SIL.ARR (MOR&EVE)'!V25,"") | O27: =IF($O$2=TRUE,CHAIN!V25,"") | P27: =IF($P$2=TRUE,'CHAIN ARR'!V25,"") | Q27: =IF($Q$2=TRUE,'DROPS ARR'!V25,"") | V27: =IF($V$2=TRUE,DROPS!V25,"") | W27: =IF($W$2=TRUE,RING!V25,"") | X27: =IF($X$2=TRUE,'EVENING CLEAN'!V25,"") | Y27: =IF($Y$2=TRUE,'DUSTBIN CHECK'!V25,"") | AD27: =IF($AD$2=TRUE,'DUSTBIN CLEAN'!V25,"") | AE27: =IF($AE$2=TRUE,'TRAY ARR'!V25,"") | AN27: =IF($AN$2=TRUE,PURSE!X25,PURSE!V25) | AO27: =IF($AO$2=TRUE,'MAADI CLEAN'!X25,'MAADI CLEAN'!V25) | AP27: =IF($AP$2=TRUE,'FAN CLEAN'!X25,'FAN CLEAN'!V25)
D29: =D3 -> CHITTAI | E29: =E3 -> CASHIER | F29: STEPS | G29: =G3 -> COLLECTION | H29: =H3 -> PATHIRAM,SL BOX | I29: =I3 -> PATHIRAM | J29: =J3 -> SL | K29: =K3 -> KOLUSU | L29: =L3 -> TEA | M29: =M3 -> MET.MKT | N29: =N3 -> SIL.ARR (MOR&EVE) | ... Q29: =Q3 -> DROPS ARRANGE | V29: =V3 -> DROPS | W29: =W3 -> RING | X29: =X3 -> EVENING CLEANING | Y29: =Y3 -> DUSTBIN CHECK | AD29: =AD3 -> DUSTBIN CLEAN | AE29: =AE3 -> TRAY ARRANGE | AG29: =AG3 -> SHOP CLOSING | AH29: =AH3 -> SHOP OPEN | AI29: =AI3 -> MOR CLEAN | AN29: =AN3 -> PURSE,BAG | AO29: =AO3 -> MAADI CLEAN | AP29: =AP3 -> FAN CLEAN
D30: =D4 | E30: =IFERROR(__xludf.DUMMYFUNCTION("IF(E2=FALSE,"""", ARRAYFORMULA(IFERROR(SPLIT(FILTER(TRANSPOSE(QUERY(TRANSPOSE(UNIQUE(E4:E27)), ,999^99)),NOT(COUNTIF(TRANSPOSE(QUERY(TRANSPOSE(A4), ,999^99)),TRANSPOSE(QUERY(TRANSPOSE(UNIQUE(E4:E27)), , 999^99))))), "" ""))))"),"") | F30: =IFERROR(__xludf.DUMMYFUNCTION("IF(F2=FALSE,"""", ARRAYFORMULA(IFERROR(SPLIT(FILTER(TRANSPOSE(QUERY(TRANSPOSE(UNIQUE(F4:F27)), ,999^99)),NOT(COUNTIF(TRANSPOSE(QUERY(TRANSPOSE(A4:A5), ,999^99)),TRANSPOSE(QUERY(TRANSPOSE(UNIQUE(F4:F27)), , 999^99))))), "" ""))))"),"") | G30: =IFERROR(__xludf.DUMMYFUNCTION("IF(G2=FALSE,"""", ARRAYFORMULA(IFERROR(SPLIT(FILTER(TRANSPOSE(QUERY(TRANSPOSE(UNIQUE(G4:G27)), ,999^99)),NOT(COUNTIF(TRANSPOSE(QUERY(TRANSPOSE(A4:A6), ,999^99)),TRANSPOSE(QUERY(TRANSPOSE(UNIQUE(G4:G27)), , 999^99))))), "" ""))))"),"VIJI-2") -> VIJI-2 | H30: =IFERROR(__xludf.DUMMYFUNCTION("IF(H2=FALSE,"""", ARRAYFORMULA(IFERROR(SPLIT(FILTER(TRANSPOSE(QUERY(TRANSPOSE(UNIQUE(H4:H27)), ,999^99)),NOT(COUNTIF(TRANSPOSE(QUERY(TRANSPOSE(A7), ,999^99)),TRANSPOSE(QUERY(TRANSPOSE(UNIQUE(H4:H27)), , 999^99))))), "" ""))))"),"RAJI-2") -> RAJI-2 | I30: =IFERROR(__xludf.DUMMYFUNCTION("IF(I2=FALSE,"""", ARRAYFORMULA(IFERROR(SPLIT(FILTER(TRANSPOSE(QUERY(TRANSPOSE(UNIQUE(I4:I27)), ,999^99)),NOT(COUNTIF(TRANSPOSE(QUERY(TRANSPOSE(A4:A9), ,999^99)),TRANSPOSE(QUERY(TRANSPOSE(UNIQUE(I4:I27)), , 999^99))))), "" ""))))"),"SAHANA") -> SAHANA | J30: =IFERROR(__xludf.DUMMYFUNCTION("IF(J2=FALSE,"""", ARRAYFORMULA(IFERROR(SPLIT(FILTER(TRANSPOSE(QUERY(TRANSPOSE(UNIQUE($J$4:$J$27)), ,999^99)),NOT(COUNTIF(TRANSPOSE(QUERY(TRANSPOSE(A4:A11), ,999^99)),TRANSPOSE(QUERY(TRANSPOSE(UNIQUE(J4:J27)), , 999^99))))), "" ""))))"),"SUDHARSHINI") -> SUDHARSHINI | K30: =IFERROR(__xludf.DUMMYFUNCTION("IF(K2=FALSE,"""", ARRAYFORMULA(IFERROR(SPLIT(FILTER(TRANSPOSE(QUERY(TRANSPOSE(UNIQUE(K4:K27)), ,999^99)),NOT(COUNTIF(TRANSPOSE(QUERY(TRANSPOSE(A4:A13), ,999^99)),TRANSPOSE(QUERY(TRANSPOSE(UNIQUE(K4:K27)), , 999^99))))), "" ""))))"),"DEEPA") -> DEEPA | L30: =IFERROR(__xludf.DUMMYFUNCTION("IF(L2=FALSE,"""", ARRAYFORMULA(IFERROR(SPLIT(FILTER(TRANSPOSE(QUERY(TRANSPOSE(UNIQUE(L4:L27)), ,999^99)),NOT(COUNTIF(TRANSPOSE(QUERY(TRANSPOSE(A4:A17), ,999^99)),TRANSPOSE(QUERY(TRANSPOSE(UNIQUE(L4:L27)), , 999^99))))), "" ""))))"),"SANTHIYA") -> SANTHIYA | M30: =IFERROR(__xludf.DUMMYFUNCTION("IF(M2=FALSE,"""", ARRAYFORMULA(IFERROR(SPLIT(FILTER(TRANSPOSE(QUERY(TRANSPOSE(UNIQUE(M4:M27)), ,999^99)),NOT(COUNTIF(TRANSPOSE(QUERY(TRANSPOSE(A4:A19), ,999^99)),TRANSPOSE(QUERY(TRANSPOSE(UNIQUE(M4:M27)), , 999^99))))), "" ""))))"),"DHANALAKSHMI") -> DHANALAKSHMI | N30: =IFERROR(__xludf.DUMMYFUNCTION("IF(N2=FALSE,"""", ARRAYFORMULA(IFERROR(SPLIT(FILTER(TRANSPOSE(QUERY(TRANSPOSE(UNIQUE(N4:N27)), ,999^99)),NOT(COUNTIF(TRANSPOSE(QUERY(TRANSPOSE(A4:A20), ,999^99)),TRANSPOSE(QUERY(TRANSPOSE(UNIQUE(N4:N27)), , 999^99))))), "" ""))))"),"CHINNAMMAL") -> CHINNAMMAL | O30: =IFERROR(__xludf.DUMMYFUNCTION("IF(O2=FALSE,"""", ARRAYFORMULA(IFERROR(SPLIT(FILTER(TRANSPOSE(QUERY(TRANSPOSE(UNIQUE(O4:O27)), ,999^99)),NOT(COUNTIF(TRANSPOSE(QUERY(TRANSPOSE(A4:A22), ,999^99)),TRANSPOSE(QUERY(TRANSPOSE(UNIQUE(O4:O27)), , 999^99))))), "" ""))))"),"NIVETHA") -> NIVETHA | P30: =IFERROR(__xludf.DUMMYFUNCTION("IF(P2=FALSE,"""", ARRAYFORMULA(IFERROR(SPLIT(FILTER(TRANSPOSE(QUERY(TRANSPOSE(UNIQUE(P4:P27)), ,999^99)),NOT(COUNTIF(TRANSPOSE(QUERY(TRANSPOSE(A4:A23), ,999^99)),TRANSPOSE(QUERY(TRANSPOSE(UNIQUE(P4:P27)), , 999^99))))), "" ""))))"),"KAVIYA") -> KAVIYA | Q30: =IFERROR(__xludf.DUMMYFUNCTION("IF(Q2=FALSE,"""",ARRAYFORMULA(IFERROR(SPLIT(FILTER(TRANSPOSE(QUERY(TRANSPOSE(UNIQUE(Q4:Q27)),,999^99)),NOT(COUNTIF(TRANSPOSE(QUERY(TRANSPOSE(FILTER(A4:A24,(A4:A24<>A7)*(A4:A24<>A18)*(A4:A24<>A19)*(A4:A24<>A21)*(A4:A24<>A22)*(A4:A24<>A25))),,999^99)),TRANS"&"POSE(QUERY(TRANSPOSE(UNIQUE(Q4:Q27)),,999^99))))),"" ""))))"),"SHANTHI") -> SHANTHI | V30: =IFERROR(__xludf.DUMMYFUNCTION("IF(V2=FALSE,"""", ARRAYFORMULA(IFERROR(SPLIT(FILTER(TRANSPOSE(QUERY(TRANSPOSE(UNIQUE(V4:V27)), ,999^99)),NOT(COUNTIF(TRANSPOSE(QUERY(TRANSPOSE(S4:S9), ,999^99)),TRANSPOSE(QUERY(TRANSPOSE(UNIQUE(V4:V27)), , 999^99))))), "" ""))))"),"JEYANTHI") -> JEYANTHI | W30: =IFERROR(__xludf.DUMMYFUNCTION("IF(W2=FALSE,"""", ARRAYFORMULA(IFERROR(SPLIT(FILTER(TRANSPOSE(QUERY(TRANSPOSE(UNIQUE(W4:W27)), ,999^99)),NOT(COUNTIF(TRANSPOSE(QUERY(TRANSPOSE(S4:S10), ,999^99)),TRANSPOSE(QUERY(TRANSPOSE(UNIQUE(W4:W27)), , 999^99))))), "" ""))))"),"CHINNAMMAL") -> CHINNAMMAL | X30: =IFERROR(__xludf.DUMMYFUNCTION("IF(X2=FALSE,"""", ARRAYFORMULA(IFERROR(SPLIT(FILTER(TRANSPOSE(QUERY(TRANSPOSE(UNIQUE(X4:X27)), ,999^99)),NOT(COUNTIF(TRANSPOSE(QUERY(TRANSPOSE(S4:S11), ,999^99)),TRANSPOSE(QUERY(TRANSPOSE(UNIQUE(X4:X27)), , 999^99))))), "" ""))))"),"RAJI-1") -> RAJI-1 | Y30: =IFERROR(__xludf.DUMMYFUNCTION("IF(Y2=FALSE,"""", ARRAYFORMULA(IFERROR(SPLIT(FILTER(TRANSPOSE(QUERY(TRANSPOSE(UNIQUE(Y4:Y27)), ,999^99)),NOT(COUNTIF(TRANSPOSE(QUERY(TRANSPOSE(S4:S12), ,999^99)),TRANSPOSE(QUERY(TRANSPOSE(UNIQUE(Y4:Y27)), , 999^99))))), "" ""))))"),"VIJI-2") -> VIJI-2 | AD30: =IFERROR(__xludf.DUMMYFUNCTION("IF(AD2=FALSE,"""", ARRAYFORMULA(IFERROR(SPLIT(FILTER(TRANSPOSE(QUERY(TRANSPOSE(UNIQUE(AD4:AD27)), ,999^99)),NOT(COUNTIF(TRANSPOSE(QUERY(TRANSPOSE(AA4:AA8), ,999^99)),TRANSPOSE(QUERY(TRANSPOSE(UNIQUE(AD4:AD27)), , 999^99))))), "" ""))))"),"SANTHIYA") -> SANTHIYA | AE30: =IFERROR(__xludf.DUMMYFUNCTION("IF(AE2=FALSE,"""", ARRAYFORMULA(IFERROR(SPLIT(FILTER(TRANSPOSE(QUERY(TRANSPOSE(UNIQUE(AE4:AE27)), ,999^99)),NOT(COUNTIF(TRANSPOSE(QUERY(TRANSPOSE(AA6:AA13), ,999^99)),TRANSPOSE(QUERY(TRANSPOSE(UNIQUE(AE4:AE27)), , 999^99))))), "" ""))))"),"MUTHUPRIYA") -> MUTHUPRIYA | AG30: =AG4 -> SAKTHIVEL 2 | AH30: =AH4 -> MANIMARAN | AI30: =AI4 -> RANI | AN30: =IFERROR(__xludf.DUMMYFUNCTION("ARRAYFORMULA(IFERROR(SPLIT(FILTER(TRANSPOSE(QUERY(TRANSPOSE(UNIQUE(AN4:AN13)), ,999^99)),NOT(COUNTIF(TRANSPOSE(QUERY(TRANSPOSE($AK$3:$AK$5), ,999^99)),TRANSPOSE(QUERY(TRANSPOSE(UNIQUE(AN4:AN13)), , 999^99))))), "" "")))"),"CHINNAMMAL") -> CHINNAMMAL | AO30: =IFERROR(__xludf.DUMMYFUNCTION("ARRAYFORMULA(IFERROR(SPLIT(FILTER(TRANSPOSE(QUERY(TRANSPOSE(UNIQUE(AO4:AO15)), ,999^99)),NOT(COUNTIF(TRANSPOSE(QUERY(TRANSPOSE($AK$3:$AK$10), ,999^99)),TRANSPOSE(QUERY(TRANSPOSE(UNIQUE(AO4:AO15)), , 999^99))))), "" "")))"),"VIDHYA") -> VIDHYA | AP30: =IFERROR(__xludf.DUMMYFUNCTION("ARRAYFORMULA(IFERROR(SPLIT(FILTER(TRANSPOSE(QUERY(TRANSPOSE(UNIQUE(AP4:AP17)), ,999^99)),NOT(COUNTIF(TRANSPOSE(QUERY(TRANSPOSE($AK$3:$AK$14), ,999^99)),TRANSPOSE(QUERY(TRANSPOSE(UNIQUE(AP4:AP17)), , 999^99))))), "" "")))"),"SHANTHI") -> SHANTHI
G31: =IFERROR(__xludf.DUMMYFUNCTION("""COMPUTED_VALUE"""),"BHARATHI") -> BHARATHI | H31: =IFERROR(__xludf.DUMMYFUNCTION("""COMPUTED_VALUE"""),"VIJI-1") -> VIJI-1 | I31: =IFERROR(__xludf.DUMMYFUNCTION("""COMPUTED_VALUE"""),"VISHNUPRIYA") -> VISHNUPRIYA | J31: =IFERROR(__xludf.DUMMYFUNCTION("""COMPUTED_VALUE"""),"VIDHYA") -> VIDHYA | K31: =IFERROR(__xludf.DUMMYFUNCTION("""COMPUTED_VALUE"""),"BHARATHI") -> BHARATHI | L31: =IFERROR(__xludf.DUMMYFUNCTION("""COMPUTED_VALUE"""),"PRIYANKA") -> PRIYANKA | M31: =IFERROR(__xludf.DUMMYFUNCTION("""COMPUTED_VALUE"""),"KAVIYA") -> KAVIYA | N31: =IFERROR(__xludf.DUMMYFUNCTION("""COMPUTED_VALUE"""),"SHANTHI") -> SHANTHI | O31: =IFERROR(__xludf.DUMMYFUNCTION("""COMPUTED_VALUE"""),"YAMUNA") -> YAMUNA | P31: =IFERROR(__xludf.DUMMYFUNCTION("""COMPUTED_VALUE"""),"MUTHUPRIYA") -> MUTHUPRIYA | Q31: =IFERROR(__xludf.DUMMYFUNCTION("""COMPUTED_VALUE"""),"VIJI-2") -> VIJI-2 | V31: =IFERROR(__xludf.DUMMYFUNCTION("""COMPUTED_VALUE"""),"VIJI-2") -> VIJI-2 | W31: =IFERROR(__xludf.DUMMYFUNCTION("""COMPUTED_VALUE"""),"VIDHYA") -> VIDHYA | X31: =IFERROR(__xludf.DUMMYFUNCTION("""COMPUTED_VALUE"""),"SAHANA") -> SAHANA | Y31: =IFERROR(__xludf.DUMMYFUNCTION("""COMPUTED_VALUE"""),"BHARATHI") -> BHARATHI | AD31: =IFERROR(__xludf.DUMMYFUNCTION("""COMPUTED_VALUE"""),"JEYANTHI") -> JEYANTHI | AE31: =IFERROR(__xludf.DUMMYFUNCTION("""COMPUTED_VALUE"""),"RAJI-1") -> RAJI-1 | AG31: =AG5 -> ARULMURUGAN | AH31: =AH5 -> ARULMURUGAN | AI31: =AI5 -> VIJI-1 | AN31: =IFERROR(__xludf.DUMMYFUNCTION("""COMPUTED_VALUE"""),"YAMUNA") -> YAMUNA | AO31: =IFERROR(__xludf.DUMMYFUNCTION("""COMPUTED_VALUE"""),"RAJI-1") -> RAJI-1 | AP31: =IFERROR(__xludf.DUMMYFUNCTION("""COMPUTED_VALUE"""),"VISHNUPRIYA") -> VISHNUPRIYA
G32: =IFERROR(__xludf.DUMMYFUNCTION("""COMPUTED_VALUE"""),"VIJI-1") -> VIJI-1 | H32: =IFERROR(__xludf.DUMMYFUNCTION("""COMPUTED_VALUE"""),"VISHNUPRIYA") -> VISHNUPRIYA | I32: =IFERROR(__xludf.DUMMYFUNCTION("""COMPUTED_VALUE"""),"YAMUNA") -> YAMUNA | J32: =IFERROR(__xludf.DUMMYFUNCTION("""COMPUTED_VALUE"""),"KAVIYA") -> KAVIYA | K32: =IFERROR(__xludf.DUMMYFUNCTION("""COMPUTED_VALUE"""),"RAJI-1") -> RAJI-1 | L32: =IFERROR(__xludf.DUMMYFUNCTION("""COMPUTED_VALUE"""),"RANI") -> RANI | M32: =IFERROR(__xludf.DUMMYFUNCTION("""COMPUTED_VALUE"""),"CHINNAMMAL") -> CHINNAMMAL | N32: =IFERROR(__xludf.DUMMYFUNCTION("""COMPUTED_VALUE"""),"KAVIYA") -> KAVIYA | O32: =IFERROR(__xludf.DUMMYFUNCTION("""COMPUTED_VALUE"""),"MUTHUPRIYA") -> MUTHUPRIYA | Q32: =IFERROR(__xludf.DUMMYFUNCTION("""COMPUTED_VALUE"""),"PRIYANKA") -> PRIYANKA | V32: =IFERROR(__xludf.DUMMYFUNCTION("""COMPUTED_VALUE"""),"VIJI-1") -> VIJI-1 | W32: =IFERROR(__xludf.DUMMYFUNCTION("""COMPUTED_VALUE"""),"SUDHARSHINI") -> SUDHARSHINI | X32: =IFERROR(__xludf.DUMMYFUNCTION("""COMPUTED_VALUE"""),"VIJI-1") -> VIJI-1 | Y32: =IFERROR(__xludf.DUMMYFUNCTION("""COMPUTED_VALUE"""),"RAJI-2") -> RAJI-2 | AD32: =IFERROR(__xludf.DUMMYFUNCTION("""COMPUTED_VALUE"""),"RAJI-1") -> RAJI-1 | AE32: =IFERROR(__xludf.DUMMYFUNCTION("""COMPUTED_VALUE"""),"SUDHARSHINI") -> SUDHARSHINI | AI32: =AI6 -> VIJI-2 | AN32: =IFERROR(__xludf.DUMMYFUNCTION("""COMPUTED_VALUE"""),"JEYANTHI") -> JEYANTHI | AO32: =IFERROR(__xludf.DUMMYFUNCTION("""COMPUTED_VALUE"""),"SAHANA") -> SAHANA | AP32: =IFERROR(__xludf.DUMMYFUNCTION("""COMPUTED_VALUE"""),"BHARATHI") -> BHARATHI
G33: =IFERROR(__xludf.DUMMYFUNCTION("""COMPUTED_VALUE"""),"DEEPA") -> DEEPA | H33: =IFERROR(__xludf.DUMMYFUNCTION("""COMPUTED_VALUE"""),"RAJI-1") -> RAJI-1 | I33: =IFERROR(__xludf.DUMMYFUNCTION("""COMPUTED_VALUE"""),"DEEPA") -> DEEPA | J33: =IFERROR(__xludf.DUMMYFUNCTION("""COMPUTED_VALUE"""),"CHINNAMMAL") -> CHINNAMMAL | K33: =IFERROR(__xludf.DUMMYFUNCTION("""COMPUTED_VALUE"""),"JEYANTHI") -> JEYANTHI | L33: =IFERROR(__xludf.DUMMYFUNCTION("""COMPUTED_VALUE"""),"DHANALAKSHMI") -> DHANALAKSHMI | M33: =IFERROR(__xludf.DUMMYFUNCTION("""COMPUTED_VALUE"""),"NIVETHA") -> NIVETHA | N33: =IFERROR(__xludf.DUMMYFUNCTION("""COMPUTED_VALUE"""),"RANI") -> RANI | Q33: =IFERROR(__xludf.DUMMYFUNCTION("""COMPUTED_VALUE"""),"SANTHIYA") -> SANTHIYA | V33: =IFERROR(__xludf.DUMMYFUNCTION("""COMPUTED_VALUE"""),"BHARATHI") -> BHARATHI | W33: =IFERROR(__xludf.DUMMYFUNCTION("""COMPUTED_VALUE"""),"BHARATHI") -> BHARATHI | X33: =IFERROR(__xludf.DUMMYFUNCTION("""COMPUTED_VALUE"""),"BHARATHI") -> BHARATHI | Y33: =IFERROR(__xludf.DUMMYFUNCTION("""COMPUTED_VALUE"""),"MUTHUPRIYA") -> MUTHUPRIYA | AD33: =IFERROR(__xludf.DUMMYFUNCTION("""COMPUTED_VALUE"""),"RAJI-2") -> RAJI-2 | AE33: =IFERROR(__xludf.DUMMYFUNCTION("""COMPUTED_VALUE"""),"YAMUNA") -> YAMUNA | AI33: =AI7 -> BHARATHI | AN33: =IFERROR(__xludf.DUMMYFUNCTION("""COMPUTED_VALUE"""),"NIVETHA") -> NIVETHA | AO33: =IFERROR(__xludf.DUMMYFUNCTION("""COMPUTED_VALUE"""),"KAVIYA") -> KAVIYA | AP33: =IFERROR(__xludf.DUMMYFUNCTION("""COMPUTED_VALUE"""),"NIVETHA") -> NIVETHA
G34: =IFERROR(__xludf.DUMMYFUNCTION("""COMPUTED_VALUE"""),"DHANALAKSHMI") -> DHANALAKSHMI | H34: =IFERROR(__xludf.DUMMYFUNCTION("""COMPUTED_VALUE"""),"YAMUNA") -> YAMUNA | I34: =IFERROR(__xludf.DUMMYFUNCTION("""COMPUTED_VALUE"""),"KAVIYA") -> KAVIYA | J34: =IFERROR(__xludf.DUMMYFUNCTION("""COMPUTED_VALUE"""),"SHANTHI") -> SHANTHI | K34: =IFERROR(__xludf.DUMMYFUNCTION("""COMPUTED_VALUE"""),"YAMUNA") -> YAMUNA | L34: =IFERROR(__xludf.DUMMYFUNCTION("""COMPUTED_VALUE"""),"NIVETHA") -> NIVETHA | M34: =IFERROR(__xludf.DUMMYFUNCTION("""COMPUTED_VALUE"""),"YAMUNA") -> YAMUNA | N34: =IFERROR(__xludf.DUMMYFUNCTION("""COMPUTED_VALUE"""),"NIVETHA") -> NIVETHA | V34: =IFERROR(__xludf.DUMMYFUNCTION("""COMPUTED_VALUE"""),"RAJI-2") -> RAJI-2 | W34: =IFERROR(__xludf.DUMMYFUNCTION("""COMPUTED_VALUE"""),"DHANALAKSHMI") -> DHANALAKSHMI | X34: =IFERROR(__xludf.DUMMYFUNCTION("""COMPUTED_VALUE"""),"SUDHARSHINI") -> SUDHARSHINI | Y34: =IFERROR(__xludf.DUMMYFUNCTION("""COMPUTED_VALUE"""),"SAHANA") -> SAHANA | AD34: =IFERROR(__xludf.DUMMYFUNCTION("""COMPUTED_VALUE"""),"VISHNUPRIYA") -> VISHNUPRIYA | AE34: =IFERROR(__xludf.DUMMYFUNCTION("""COMPUTED_VALUE"""),"VIJI-1") -> VIJI-1 | AN34: =IFERROR(__xludf.DUMMYFUNCTION("""COMPUTED_VALUE"""),"RAJI-1") -> RAJI-1 | AO34: =IFERROR(__xludf.DUMMYFUNCTION("""COMPUTED_VALUE"""),"JEYANTHI") -> JEYANTHI | AP34: =IFERROR(__xludf.DUMMYFUNCTION("""COMPUTED_VALUE"""),"PRIYANKA") -> PRIYANKA
G35: =IFERROR(__xludf.DUMMYFUNCTION("""COMPUTED_VALUE"""),"RAJI-1") -> RAJI-1 | H35: =IFERROR(__xludf.DUMMYFUNCTION("""COMPUTED_VALUE"""),"CHINNAMMAL") -> CHINNAMMAL | I35: =IFERROR(__xludf.DUMMYFUNCTION("""COMPUTED_VALUE"""),"MUTHUPRIYA") -> MUTHUPRIYA | J35: =IFERROR(__xludf.DUMMYFUNCTION("""COMPUTED_VALUE"""),"NIVETHA") -> NIVETHA | K35: =IFERROR(__xludf.DUMMYFUNCTION("""COMPUTED_VALUE"""),"MUTHUPRIYA") -> MUTHUPRIYA | L35: =IFERROR(__xludf.DUMMYFUNCTION("""COMPUTED_VALUE"""),"MUTHUPRIYA") -> MUTHUPRIYA | M35: =IFERROR(__xludf.DUMMYFUNCTION("""COMPUTED_VALUE"""),"SHANTHI") -> SHANTHI | N35: =IFERROR(__xludf.DUMMYFUNCTION("""COMPUTED_VALUE"""),"PANJU") -> PANJU | V35: =IFERROR(__xludf.DUMMYFUNCTION("""COMPUTED_VALUE"""),"DEEPA") -> DEEPA | W35: =IFERROR(__xludf.DUMMYFUNCTION("""COMPUTED_VALUE"""),"YAMUNA") -> YAMUNA | X35: =IFERROR(__xludf.DUMMYFUNCTION("""COMPUTED_VALUE"""),"RANI") -> RANI | Y35: =IFERROR(__xludf.DUMMYFUNCTION("""COMPUTED_VALUE"""),"RANI") -> RANI | AD35: =IFERROR(__xludf.DUMMYFUNCTION("""COMPUTED_VALUE"""),"DEEPA") -> DEEPA | AE35: =IFERROR(__xludf.DUMMYFUNCTION("""COMPUTED_VALUE"""),"VISHNUPRIYA") -> VISHNUPRIYA | AN35: =IFERROR(__xludf.DUMMYFUNCTION("""COMPUTED_VALUE"""),"VIJI-2") -> VIJI-2 | AO35: =IFERROR(__xludf.DUMMYFUNCTION("""COMPUTED_VALUE"""),"PANJU") -> PANJU | AP35: =IFERROR(__xludf.DUMMYFUNCTION("""COMPUTED_VALUE"""),"DEEPA") -> DEEPA
H36: =IFERROR(__xludf.DUMMYFUNCTION("""COMPUTED_VALUE"""),"SAHANA") -> SAHANA | I36: =IFERROR(__xludf.DUMMYFUNCTION("""COMPUTED_VALUE"""),"SANTHIYA") -> SANTHIYA | J36: =IFERROR(__xludf.DUMMYFUNCTION("""COMPUTED_VALUE"""),"RAJI-1") -> RAJI-1 | K36: =IFERROR(__xludf.DUMMYFUNCTION("""COMPUTED_VALUE"""),"SANTHIYA") -> SANTHIYA | L36: =IFERROR(__xludf.DUMMYFUNCTION("""COMPUTED_VALUE"""),"PANJU") -> PANJU | M36: =IFERROR(__xludf.DUMMYFUNCTION("""COMPUTED_VALUE"""),"MUTHUPRIYA") -> MUTHUPRIYA | V36: =IFERROR(__xludf.DUMMYFUNCTION("""COMPUTED_VALUE"""),"VISHNUPRIYA") -> VISHNUPRIYA | W36: =IFERROR(__xludf.DUMMYFUNCTION("""COMPUTED_VALUE"""),"VISHNUPRIYA") -> VISHNUPRIYA | X36: =IFERROR(__xludf.DUMMYFUNCTION("""COMPUTED_VALUE"""),"MUTHUPRIYA") -> MUTHUPRIYA | Y36: =IFERROR(__xludf.DUMMYFUNCTION("""COMPUTED_VALUE"""),"YAMUNA") -> YAMUNA | AD36: =IFERROR(__xludf.DUMMYFUNCTION("""COMPUTED_VALUE"""),"CHINNAMMAL") -> CHINNAMMAL | AE36: =IFERROR(__xludf.DUMMYFUNCTION("""COMPUTED_VALUE"""),"DHANALAKSHMI") -> DHANALAKSHMI | AN36: =IFERROR(__xludf.DUMMYFUNCTION("""COMPUTED_VALUE"""),"DEEPA") -> DEEPA | AO36: =IFERROR(__xludf.DUMMYFUNCTION("""COMPUTED_VALUE"""),"DEEPA") -> DEEPA | AP36: =IFERROR(__xludf.DUMMYFUNCTION("""COMPUTED_VALUE"""),"PANJU") -> PANJU
H37: =IFERROR(__xludf.DUMMYFUNCTION("""COMPUTED_VALUE"""),"SUDHARSHINI") -> SUDHARSHINI | I37: =IFERROR(__xludf.DUMMYFUNCTION("""COMPUTED_VALUE"""),"NIVETHA") -> NIVETHA | J37: =IFERROR(__xludf.DUMMYFUNCTION("""COMPUTED_VALUE"""),"BHARATHI") -> BHARATHI | K37: =IFERROR(__xludf.DUMMYFUNCTION("""COMPUTED_VALUE"""),"DHANALAKSHMI") -> DHANALAKSHMI | L37: =IFERROR(__xludf.DUMMYFUNCTION("""COMPUTED_VALUE"""),"SHANTHI") -> SHANTHI | V37: =IFERROR(__xludf.DUMMYFUNCTION("""COMPUTED_VALUE"""),"DHANALAKSHMI") -> DHANALAKSHMI | W37: =IFERROR(__xludf.DUMMYFUNCTION("""COMPUTED_VALUE"""),"VIJI-1") -> VIJI-1 | X37: =IFERROR(__xludf.DUMMYFUNCTION("""COMPUTED_VALUE"""),"RAJI-2") -> RAJI-2 | Y37: =IFERROR(__xludf.DUMMYFUNCTION("""COMPUTED_VALUE"""),"KAVIYA") -> KAVIYA | AD37: =IFERROR(__xludf.DUMMYFUNCTION("""COMPUTED_VALUE"""),"SUDHARSHINI") -> SUDHARSHINI | AE37: =IFERROR(__xludf.DUMMYFUNCTION("""COMPUTED_VALUE"""),"PRIYANKA") -> PRIYANKA | AN37: =IFERROR(__xludf.DUMMYFUNCTION("""COMPUTED_VALUE"""),"MUTHUPRIYA") -> MUTHUPRIYA | AO37: =IFERROR(__xludf.DUMMYFUNCTION("""COMPUTED_VALUE"""),"DHANALAKSHMI") -> DHANALAKSHMI | AP37: =IFERROR(__xludf.DUMMYFUNCTION("""COMPUTED_VALUE"""),"SANTHIYA") -> SANTHIYA
H38: =IFERROR(__xludf.DUMMYFUNCTION("""COMPUTED_VALUE"""),"JEYANTHI") -> JEYANTHI | I38: =IFERROR(__xludf.DUMMYFUNCTION("""COMPUTED_VALUE"""),"PRIYANKA") -> PRIYANKA | J38: =IFERROR(__xludf.DUMMYFUNCTION("""COMPUTED_VALUE"""),"YAMUNA") -> YAMUNA | K38: =IFERROR(__xludf.DUMMYFUNCTION("""COMPUTED_VALUE"""),"PRIYANKA") -> PRIYANKA | V38: =IFERROR(__xludf.DUMMYFUNCTION("""COMPUTED_VALUE"""),"SUDHARSHINI") -> SUDHARSHINI | W38: =IFERROR(__xludf.DUMMYFUNCTION("""COMPUTED_VALUE"""),"DEEPA") -> DEEPA | X38: =IFERROR(__xludf.DUMMYFUNCTION("""COMPUTED_VALUE"""),"VIJI-2") -> VIJI-2 | Y38: =IFERROR(__xludf.DUMMYFUNCTION("""COMPUTED_VALUE"""),"VISHNUPRIYA") -> VISHNUPRIYA | AD38: =IFERROR(__xludf.DUMMYFUNCTION("""COMPUTED_VALUE"""),"PANJU") -> PANJU | AE38: =IFERROR(__xludf.DUMMYFUNCTION("""COMPUTED_VALUE"""),"VIDHYA") -> VIDHYA | AN38: =IFERROR(__xludf.DUMMYFUNCTION("""COMPUTED_VALUE"""),"SANTHIYA") -> SANTHIYA | AO38: =IFERROR(__xludf.DUMMYFUNCTION("""COMPUTED_VALUE"""),"RAJI-2") -> RAJI-2
H39: =IFERROR(__xludf.DUMMYFUNCTION("""COMPUTED_VALUE"""),"KAVIYA") -> KAVIYA | I39: =IFERROR(__xludf.DUMMYFUNCTION("""COMPUTED_VALUE"""),"DHANALAKSHMI") -> DHANALAKSHMI | J39: =IFERROR(__xludf.DUMMYFUNCTION("""COMPUTED_VALUE"""),"DHANALAKSHMI") -> DHANALAKSHMI | K39: =IFERROR(__xludf.DUMMYFUNCTION("""COMPUTED_VALUE"""),"SHANTHI") -> SHANTHI | V39: =IFERROR(__xludf.DUMMYFUNCTION("""COMPUTED_VALUE"""),"MUTHUPRIYA") -> MUTHUPRIYA | W39: =IFERROR(__xludf.DUMMYFUNCTION("""COMPUTED_VALUE"""),"MUTHUPRIYA") -> MUTHUPRIYA | X39: =IFERROR(__xludf.DUMMYFUNCTION("""COMPUTED_VALUE"""),"PANJU") -> PANJU | Y39: =IFERROR(__xludf.DUMMYFUNCTION("""COMPUTED_VALUE"""),"PANJU") -> PANJU | AD39: =IFERROR(__xludf.DUMMYFUNCTION("""COMPUTED_VALUE"""),"SHANTHI") -> SHANTHI | AE39: =IFERROR(__xludf.DUMMYFUNCTION("""COMPUTED_VALUE"""),"BHARATHI") -> BHARATHI | AN39: =IFERROR(__xludf.DUMMYFUNCTION("""COMPUTED_VALUE"""),"RAJI-2") -> RAJI-2
H40: =IFERROR(__xludf.DUMMYFUNCTION("""COMPUTED_VALUE"""),"MUTHUPRIYA") -> MUTHUPRIYA | I40: =IFERROR(__xludf.DUMMYFUNCTION("""COMPUTED_VALUE"""),"JEYANTHI") -> JEYANTHI | J40: =IFERROR(__xludf.DUMMYFUNCTION("""COMPUTED_VALUE"""),"MUTHUPRIYA") -> MUTHUPRIYA | V40: =IFERROR(__xludf.DUMMYFUNCTION("""COMPUTED_VALUE"""),"SAHANA") -> SAHANA | W40: =IFERROR(__xludf.DUMMYFUNCTION("""COMPUTED_VALUE"""),"RAJI-1") -> RAJI-1 | X40: =IFERROR(__xludf.DUMMYFUNCTION("""COMPUTED_VALUE"""),"VISHNUPRIYA") -> VISHNUPRIYA | Y40: =IFERROR(__xludf.DUMMYFUNCTION("""COMPUTED_VALUE"""),"VIJI-1") -> VIJI-1 | AD40: =IFERROR(__xludf.DUMMYFUNCTION("""COMPUTED_VALUE"""),"KAVIYA") -> KAVIYA
H41: =IFERROR(__xludf.DUMMYFUNCTION("""COMPUTED_VALUE"""),"RANI") -> RANI | I41: =IFERROR(__xludf.DUMMYFUNCTION("""COMPUTED_VALUE"""),"RAJI-1") -> RAJI-1 | J41: =IFERROR(__xludf.DUMMYFUNCTION("""COMPUTED_VALUE"""),"SANTHIYA") -> SANTHIYA | V41: =IFERROR(__xludf.DUMMYFUNCTION("""COMPUTED_VALUE"""),"CHINNAMMAL") -> CHINNAMMAL | W41: =IFERROR(__xludf.DUMMYFUNCTION("""COMPUTED_VALUE"""),"SAHANA") -> SAHANA | Y41: =IFERROR(__xludf.DUMMYFUNCTION("""COMPUTED_VALUE"""),"DHANALAKSHMI") -> DHANALAKSHMI | AD41: =IFERROR(__xludf.DUMMYFUNCTION("""COMPUTED_VALUE"""),"YAMUNA") -> YAMUNA
...

Sheet STAFFS
A1: DOOR OPEN | C1: DOOR CLOSING | E1: MOR CLEAN | G1: FAN CLEAN | I1: MAADI CLEAN | K1: CHITTAI | M1: STEPS | O1: CASH | Q1: MET.MKT | S1: KOLUSU | U1: PATHIRAM | W1: SL | Y1: TEA | AA1: PURSE | AC1: CHAIN | AE1: DROPS | AG1: RING | AI1: EVENING CLEAN | AK1: DUSTBIN CHECK | AM1: CHAIN ARR | AO1: SIL.ARR (MOR&EVE) | AQ1: DUSTBIN CLEAN | AS1: TRAY ARR | AU1: PATHIRAM,SL BOX | AW1: DROPS ARR | AY1: COLLECTION
A2: ARIVUNITHI | C2: ARIVUNITHI | E2: BHARATHI | G2: BHARATHI | I2: BHARATHI | K2: BHARATHI | M2: CHINNAMMAL | O2: CHINNAMMAL | Q2: BHARATHI | S2: BHARATHI | U2: BHARATHI | W2: BHARATHI | Y2: BHARATHI | AA2: BHARATHI | AC2: BHARATHI | AE2: BHARATHI | AG2: BHARATHI | AI2: BHARATHI | AK2: BHARATHI | AM2: BHARATHI | AO2: BHARATHI | AQ2: BHARATHI | AS2: BHARATHI | AU2: BHARATHI | AW2: BHARATHI | AY2: BHARATHI
A3: ARULMURUGAN | C3: ARULMURUGAN | E3: CHINNAMMAL | G3: CHINNAMMAL | I3: CHINNAMMAL | K3: DEEPA | M3: JEYANTHI | O3: JEYANTHI | Q3: CHINNAMMAL | S3: CHINNAMMAL | U3: CHINNAMMAL | W3: CHINNAMMAL | Y3: CHINNAMMAL | AA3: CHINNAMMAL | AC3: CHINNAMMAL | AE3: CHINNAMMAL | AG3: CHINNAMMAL | AI3: CHINNAMMAL | AK3: CHINNAMMAL | AM3: CHINNAMMAL | AO3: CHINNAMMAL | AQ3: CHINNAMMAL | AS3: CHINNAMMAL | AU3: CHINNAMMAL | AW3: CHINNAMMAL | AY3: DEEPA
A4: BALAMURUGAN | C4: BALAMURUGAN | E4: DEEPA | G4: DEEPA | I4: DEEPA | K4: DHANALAKSHMI | M4: KAVIYA | O4: SAHANA | Q4: DEEPA | S4: DEEPA | U4: DEEPA | W4: DEEPA | Y4: DEEPA | AA4: DEEPA | AC4: DEEPA | AE4: DEEPA | AG4: DEEPA | AI4: DEEPA | AK4: DEEPA | AM4: DEEPA | AO4: DEEPA | AQ4: DEEPA | AS4: DEEPA | AU4: DEEPA | AW4: DEEPA | AY4: DHANALAKSHMI
A5: BALASUBRAMANIYAN | C5: BALASUBRAMANI | E5: DHANALAKSHMI | G5: DHANALAKSHMI | I5: DHANALAKSHMI | K5: RAJI-1 | M5: MUTHUPRIYA | O5: SUDHARSHINI | Q5: DHANALAKSHMI | S5: DHANALAKSHMI | U5: DHANALAKSHMI | W5: DHANALAKSHMI | Y5: DHANALAKSHMI | AA5: DHANALAKSHMI | AC5: DHANALAKSHMI | AE5: DHANALAKSHMI | AG5: DHANALAKSHMI | AI5: DHANALAKSHMI | AK5: DHANALAKSHMI | AM5: DHANALAKSHMI | AO5: DHANALAKSHMI | AQ5: DHANALAKSHMI | AS5: DHANALAKSHMI | AU5: DHANALAKSHMI | AW5: DHANALAKSHMI | AY5: RAJI-1
A6: KOLANCHIYAPPAN | C6: KOLANCHIYAPPAN | E6: JEYANTHI | G6: JEYANTHI | I6: JEYANTHI | K6: RAJI-2 | M6: PRIYANKA | O6: YAMUNA | Q6: JEYANTHI | S6: JEYANTHI | U6: JEYANTHI | W6: JEYANTHI | Y6: JEYANTHI | AA6: JEYANTHI | AC6: JEYANTHI | AE6: JEYANTHI | AG6: JEYANTHI | AI6: JEYANTHI | AK6: JEYANTHI | AM6: JEYANTHI | AO6: JEYANTHI | AQ6: JEYANTHI | AS6: JEYANTHI | AU6: JEYANTHI | AW6: JEYANTHI | AY6: RAJI-2
A7: MANIMARAN | C7: MANIMARAN | E7: KAVIYA | G7: KAVIYA | I7: KAVIYA | K7: VIJI-1 | M7: SAHANA | Q7: KAVIYA | S7: KAVIYA | U7: KAVIYA | W7: KAVIYA | Y7: KAVIYA | AA7: KAVIYA | AC7: MUTHUPRIYA | AE7: MUTHUPRIYA | AG7: MUTHUPRIYA | AI7: KAVIYA | AK7: KAVIYA | AM7: KAVIYA | AO7: KAVIYA | AQ7: KAVIYA | AS7: KAVIYA | AU7: KAVIYA | AW7: KAVIYA | AY7: VIJI-1
A8: MUTHUKUMAR | C8: MUTHUKUMAR | E8: MUTHUPRIYA | G8: MUTHUPRIYA | I8: MUTHUPRIYA | K8: VIJI-2 | M8: SANTHIYA | Q8: MUTHUPRIYA | S8: MUTHUPRIYA | U8: MUTHUPRIYA | W8: MUTHUPRIYA | Y8: MUTHUPRIYA | AA8: MUTHUPRIYA | AC8: NIVETHA | AE8: NIVETHA | AG8: NIVETHA | AI8: MUTHUPRIYA | AK8: MUTHUPRIYA | AM8: MUTHUPRIYA | AO8: MUTHUPRIYA | AQ8: MUTHUPRIYA | AS8: MUTHUPRIYA | AU8: MUTHUPRIYA | AW8: MUTHUPRIYA | AY8: VIJI-2
A9: PANDI-2 | C9: PANDI-2 | E9: NIVETHA | G9: NIVETHA | I9: NIVETHA | K9: YOGAPRIYA | M9: SHANTHI | Q9: NIVETHA | S9: NIVETHA | U9: NIVETHA | W9: NIVETHA | Y9: NIVETHA | AA9: NIVETHA | AC9: RAJI-1 | AE9: RAJI-1 | AG9: RAJI-1 | AI9: NIVETHA | AK9: NIVETHA | AM9: NIVETHA | AO9: NIVETHA | AQ9: NIVETHA | AS9: NIVETHA | AU9: NIVETHA | AW9: NIVETHA | AY9: YOGAPRIYA
A10: RAJKUMAR | C10: PANDIKUMAR | E10: PANJU | G10: PANJU | I10: PANJU | M10: SUDHARSHINI | Q10: PRIYANKA | S10: PRIYANKA | U10: PRIYANKA | W10: PRIYANKA | Y10: PANJU | AA10: PANJU | AC10: RAJI-2 | AE10: RAJI-2 | AG10: RAJI-2 | AI10: PANJU | AK10: PANJU | AM10: PRIYANKA | AO10: PANJU | AQ10: PANJU | AS10: PRIYANKA | AU10: PANJU | AW10: PRIYANKA
A11: SAKTHIVEL 2 | C11: PARIMANAM | E11: PRIYANKA | G11: PRIYANKA | I11: PRIYANKA | M11: YAMUNA | Q11: RAJI-1 | S11: RAJI-1 | U11: RAJI-1 | W11: RAJI-1 | Y11: PRIYANKA | AA11: PRIYANKA | AC11: SAHANA | AE11: SAHANA | AG11: SAHANA | AI11: PRIYANKA | AK11: PRIYANKA | AM11: RAJI-1 | AO11: PRIYANKA | AQ11: PRIYANKA | AS11: RAJI-1 | AU11: PRIYANKA | AW11: RAJI-1
A12: SATHISH | C12: RAJKUMAR | E12: RAJI-1 | G12: RAJI-1 | I12: RAJI-1 | Q12: RAJI-2 | S12: RAJI-2 | U12: RAJI-2 | W12: RAJI-2 | Y12: RAJI-1 | AA12: RAJI-1 | AC12: SUDHARSHINI | AE12: SUDHARSHINI | AG12: SUDHARSHINI | AI12: RAJI-1 | AK12: RAJI-1 | AM12: RAJI-2 | AO12: RAJI-1 | AQ12: RAJI-1 | AS12: RAJI-2 | AU12: RAJI-1 | AW12: RAJI-2
A13: SELVENDRAN | C13: SAKTHIVEL 2 | E13: RAJI-2 | G13: RAJI-2 | I13: RAJI-2 | Q13: SAHANA | S13: SAHANA | U13: SAHANA | W13: SAHANA | Y13: RAJI-2 | AA13: RAJI-2 | AC13: VIDHYA | AE13: VIDHYA | AG13: VIDHYA | AI13: RAJI-2 | AK13: RAJI-2 | AM13: SAHANA | AO13: RAJI-2 | AQ13: RAJI-2 | AS13: SAHANA | AU13: RAJI-2 | AW13: SAHANA
A14: SYED ABUTHAHIR | C14: SATHISH | E14: RANI | G14: RANI | I14: RANI | Q14: SANTHIYA | S14: SANTHIYA | U14: SANTHIYA | W14: SANTHIYA | Y14: RANI | AA14: RANI | AC14: VIJI-1 | AE14: VIJI-1 | AG14: VIJI-1 | AI14: RANI | AK14: RANI | AM14: SANTHIYA | AO14: RANI | AQ14: RANI | AS14: SANTHIYA | AU14: RANI | AW14: SANTHIYA
A15: THAMODARAN | C15: SELVENDRAN | E15: SAHANA | G15: SAHANA | I15: SAHANA | Q15: SHANTHI | S15: SHANTHI | U15: SHANTHI | W15: SHANTHI | Y15: SAHANA | AA15: SAHANA | AC15: VIJI-2 | AE15: VIJI-2 | AG15: VIJI-2 | AI15: SAHANA | AK15: SAHANA | AM15: SHANTHI | AO15: SAHANA | AQ15: SAHANA | AS15: SHANTHI | AU15: SAHANA | AW15: SHANTHI
A16: VENKADESAN | C16: SYED ABUTHAHIR | E16: SANTHIYA | G16: SANTHIYA | I16: SANTHIYA | Q16: SUDHARSHINI | S16: SUDHARSHINI | U16: SUDHARSHINI | W16: SUDHARSHINI | Y16: SANTHIYA | AA16: SANTHIYA | AC16: VISHNUPRIYA | AE16: VISHNUPRIYA | AG16: VISHNUPRIYA | AI16: SANTHIYA | AK16: SANTHIYA | AM16: SUDHARSHINI | AO16: SANTHIYA | AQ16: SANTHIYA | AS16: SUDHARSHINI | AU16: SANTHIYA | AW16: SUDHARSHINI
C17: THAMODARAN | E17: SHANTHI | G17: SHANTHI | I17: SHANTHI | Q17: VIDHYA | S17: VIDHYA | U17: VIDHYA | W17: VIDHYA | Y17: SHANTHI | AA17: SHANTHI | AC17: YAMUNA | AE17: YAMUNA | AG17: YAMUNA | AI17: SHANTHI | AK17: SHANTHI | AM17: VIDHYA | AO17: SHANTHI | AQ17: SHANTHI | AS17: VIDHYA | AU17: SHANTHI | AW17: VIDHYA
C18: VENKADESAN | E18: SUDHARSHINI | G18: SUDHARSHINI | I18: SUDHARSHINI | Q18: VIJI-1 | S18: VIJI-1 | U18: VIJI-1 | W18: VIJI-1 | Y18: SUDHARSHINI | AA18: SUDHARSHINI | AC18: YOGAPRIYA | AE18: YOGAPRIYA | AG18: YOGAPRIYA | AI18: SUDHARSHINI | AK18: SUDHARSHINI | AM18: VIJI-1 | AO18: SUDHARSHINI | AQ18: SUDHARSHINI | AS18: VIJI-1 | AU18: SUDHARSHINI | AW18: VIJI-1
E19: VIDHYA | G19: VIDHYA | I19: VIDHYA | Q19: VIJI-2 | S19: VIJI-2 | U19: VIJI-2 | W19: VIJI-2 | Y19: VIDHYA | AA19: VIDHYA | AI19: VIDHYA | AK19: VIDHYA | AM19: VIJI-2 | AO19: VIDHYA | AQ19: VIDHYA | AS19: VIJI-2 | AU19: VIDHYA | AW19: VIJI-2
E20: VIJI-1 | G20: VIJI-1 | I20: VIJI-1 | Q20: VISHNUPRIYA | S20: VISHNUPRIYA | U20: VISHNUPRIYA | W20: VISHNUPRIYA | Y20: VIJI-1 | AA20: VIJI-1 | AI20: VIJI-1 | AK20: VIJI-1 | AM20: VISHNUPRIYA | AO20: VIJI-1 | AQ20: VIJI-1 | AS20: VISHNUPRIYA | AU20: VIJI-1 | AW20: VISHNUPRIYA
E21: VIJI-2 | G21: VIJI-2 | I21: VIJI-2 | Q21: YAMUNA | S21: YAMUNA | U21: YAMUNA | W21: YAMUNA | Y21: VIJI-2 | AA21: VIJI-2 | AI21: VIJI-2 | AK21: VIJI-2 | AM21: YAMUNA | AO21: VIJI-2 | AQ21: VIJI-2 | AS21: YAMUNA | AU21: VIJI-2 | AW21: YAMUNA
E22: VISHNUPRIYA | G22: VISHNUPRIYA | I22: VISHNUPRIYA | Q22: YOGAPRIYA | S22: YOGAPRIYA | U22: YOGAPRIYA | W22: YOGAPRIYA | Y22: VISHNUPRIYA | AA22: VISHNUPRIYA | AI22: VISHNUPRIYA | AK22: VISHNUPRIYA | AM22: YOGAPRIYA | AO22: VISHNUPRIYA | AQ22: VISHNUPRIYA | AS22: YOGAPRIYA | AU22: VISHNUPRIYA | AW22: YOGAPRIYA
E23: YAMUNA | G23: YAMUNA | I23: YAMUNA | Y23: YAMUNA | AA23: YAMUNA | AI23: YAMUNA | AK23: YAMUNA | AO23: YAMUNA | AQ23: YAMUNA | AU23: YAMUNA
E24: YOGAPRIYA | G24: YOGAPRIYA | I24: YOGAPRIYA | Y24: YOGAPRIYA | AA24: YOGAPRIYA | AI24: YOGAPRIYA | AK24: YOGAPRIYA | AO24: YOGAPRIYA | AQ24: YOGAPRIYA | AU24: YOGAPRIYA

Sheet LEAVE
A1: LADIES LEAVE | B1: GENTS LEAVE
A2: YOGAPRIYA

Sheet STOCKS 
E1: =TODAY()+1 -> 46178
